Workbook

Sheet Grupēta tāme
A1: Cenu piedāvājums Nr.G 033 V/26 I — grupēts pēc līdzīgiem darbiem
A2: OBJEKTS: Šmerļa ielā 3a, Rīgā. | L2: Datums: 16.06.2026
A4: Vienā rindā apvienotas tikai salīdzināmas pozīcijas ar vienādu efektīvo biezumu un vienības izmaksām. Kolonnā “Avota pozīcijas” saglabāta saite uz sākotnējās tāmes sadaļām.
A6: Npk. | B6: Darbu grupa | C6: Darbu un izdevumu nosaukums | D6: Biezums / mm | E6: Mērv. | F6: Daudzums | G6: Darbs / vien. | H6: Materiāli / vien. | I6: Mehānismi / vien. | J6: Vienības cena | K6: Darbs kopā | L6: Materiāli kopā | M6: Mehānismi kopā | N6: Summa EUR | O6: Avota pozīcijas
A7: 1. Sagatavošana un pamatne
A8: 1 | B8: Sagatavošana un pamatne | C8: Smilts līdzināšana (vid. 25 mm) | D8: 25 | E8: m2 | F8: =SUM('Oriģinālā tāme'!F62,'Oriģinālā tāme'!F67,'Oriģinālā tāme'!F72,'Oriģinālā tāme'!F77) -> 1931.01 | G8: ='Oriģinālā tāme'!G62 -> 1.75 | H8: ='Oriģinālā tāme'!H62 -> 1.32 | I8: ='Oriģinālā tāme'!I62 -> 0.35 | J8: =SUM(G8:I8) -> 3.42 | K8: =SUM('Oriģinālā tāme'!K62,'Oriģinālā tāme'!K67,'Oriģinālā tāme'!K72,'Oriģinālā tāme'!K77) -> 3379.2675 | L8: =SUM('Oriģinālā tāme'!L62,'Oriģinālā tāme'!L67,'Oriģinālā tāme'!L72,'Oriģinālā tāme'!L77) -> 2548.9332 | M8: =SUM('Oriģinālā tāme'!M62,'Oriģinālā tāme'!M67,'Oriģinālā tāme'!M72,'Oriģinālā tāme'!M77) -> 675.8535 | N8: =SUM(5117.21,1382.23,88.31,16.32) -> 6604.07 | O8: PA1.6; PA1.7; PA1.8; PA1.9
A9: Grupas starpsumma | K9: =SUM(K8:K8) -> 3379.2675 | L9: =SUM(L8:L8) -> 2548.9332 | M9: =SUM(M8:M8) -> 675.8535 | N9: =SUM(N8:N8) -> 6604.07
A11: 2. Siltumizolācija
A12: 2 | B12: Siltumizolācija | C12: ThermoWhite izolācijas slānis (vid. 45 mm) | D12: 45 | E12: m2 | F12: =SUM('Oriģinālā tāme'!F42,'Oriģinālā tāme'!F50,'Oriģinālā tāme'!F55) -> 3156.93 | G12: ='Oriģinālā tāme'!G42 -> 1.7325 | H12: ='Oriģinālā tāme'!H42 -> 5.175 | I12: ='Oriģinālā tāme'!I42 -> 1.0125 | J12: =SUM(G12:I12) -> 7.92 | K12: =SUM('Oriģinālā tāme'!K42,'Oriģinālā tāme'!K50,'Oriģinālā tāme'!K55) -> 5469.3812 | L12: =SUM('Oriģinālā tāme'!L42,'Oriģinālā tāme'!L50,'Oriģinālā tāme'!L55) -> 16337.113 | M12: =SUM('Oriģinālā tāme'!M42,'Oriģinālā tāme'!M50,'Oriģinālā tāme'!M55) -> 3196.3916 | N12: =SUM(21736.84,3089.59,176.45) -> 25002.88 | O12: PA1.1; PA1.3; PA1.4
A13: 3 | B13: Siltumizolācija | C13: XPS putupolistirols 300 kPa (150 mm) | D13: 150 | E13: m2 | F13: =SUM('Oriģinālā tāme'!F63,'Oriģinālā tāme'!F68,'Oriģinālā tāme'!F73,'Oriģinālā tāme'!F78) -> 1931.01 | G13: ='Oriģinālā tāme'!G63 -> 2.05 | H13: ='Oriģinālā tāme'!H63 -> 18 | I13: ='Oriģinālā tāme'!I63 -> 0.25 | J13: =SUM(G13:I13) -> 20.3 | K13: =SUM('Oriģinālā tāme'!K63,'Oriģinālā tāme'!K68,'Oriģinālā tāme'!K73,'Oriģinālā tāme'!K78) -> 3958.5705 | L13: =SUM('Oriģinālā tāme'!L63,'Oriģinālā tāme'!L68,'Oriģinālā tāme'!L73,'Oriģinālā tāme'!L78) -> 34758.18 | M13: =SUM('Oriģinālā tāme'!M63,'Oriģinālā tāme'!M68,'Oriģinālā tāme'!M73,'Oriģinālā tāme'!M78) -> 482.7525 | N13: =SUM(30374.08,8204.45,524.15,96.83) -> 39199.51 | O13: PA1.6; PA1.7; PA1.8; PA1.9
A14: Grupas starpsumma | K14: =SUM(K12:K13) -> 9427.9517 | L14: =SUM(L12:L13) -> 51095.293 | M14: =SUM(M12:M13) -> 3679.1441 | N14: =SUM(N12:N13) -> 64202.39
A16: 3. Plēves un starpslāņi
A17: 4 | B17: Plēves un starpslāņi | C17: PEPI TRAFO 7 mm starpslānis | E17: m2 | F17: =SUM('Oriģinālā tāme'!F43,'Oriģinālā tāme'!F47,'Oriģinālā tāme'!F51,'Oriģinālā tāme'!F56) -> 3792.85 | G17: ='Oriģinālā tāme'!G43 -> 0.35 | H17: ='Oriģinālā tāme'!H43 -> 2.79 | I17: ='Oriģinālā tāme'!I43 -> 0.18 | J17: =SUM(G17:I17) -> 3.32 | K17: =SUM('Oriģinālā tāme'!K43,'Oriģinālā tāme'!K47,'Oriģinālā tāme'!K51,'Oriģinālā tāme'!K56) -> 1327.4975 | L17: =SUM('Oriģinālā tāme'!L43,'Oriģinālā tāme'!L47,'Oriģinālā tāme'!L51,'Oriģinālā tāme'!L56) -> 10582.052 | M17: =SUM('Oriģinālā tāme'!M43,'Oriģinālā tāme'!M47,'Oriģinālā tāme'!M51,'Oriģinālā tāme'!M56) -> 682.713 | N17: =SUM(9111.9,2111.26,1295.14,73.97) -> 12592.27 | O17: PA1.1; PA1.2; PA1.3; PA1.4
A18: 5 | B18: Plēves un starpslāņi | C18: Plēve atbilstoši ThermoWhite sistēmai | E18: m2 | F18: =SUM('Oriģinālā tāme'!F44,'Oriģinālā tāme'!F52,'Oriģinālā tāme'!F57) -> 3156.93 | G18: ='Oriģinālā tāme'!G44 -> 0.35 | H18: ='Oriģinālā tāme'!H44 -> 0.89 | I18: ='Oriģinālā tāme'!I44 -> 0.08 | J18: =SUM(G18:I18) -> 1.32 | K18: =SUM('Oriģinālā tāme'!K44,'Oriģinālā tāme'!K52,'Oriģinālā tāme'!K57) -> 1104.9255 | L18: =SUM('Oriģinālā tāme'!L44,'Oriģinālā tāme'!L52,'Oriģinālā tāme'!L57) -> 2809.6677 | M18: =SUM('Oriģinālā tāme'!M44,'Oriģinālā tāme'!M52,'Oriģinālā tāme'!M57) -> 252.5544 | N18: =SUM(3622.8,514.94,29.41) -> 4167.15 | O18: PA1.1; PA1.3; PA1.4
A19: 6 | B19: Plēves un starpslāņi | C19: Hidroizolācijas plēve | E19: m2 | F19: =SUM('Oriģinālā tāme'!F64,'Oriģinālā tāme'!F69,'Oriģinālā tāme'!F74,'Oriģinālā tāme'!F79) -> 1931.01 | G19: ='Oriģinālā tāme'!G64 -> 0.35 | H19: ='Oriģinālā tāme'!H64 -> 0.89 | I19: ='Oriģinālā tāme'!I64 -> 0.08 | J19: =SUM(G19:I19) -> 1.32 | K19: =SUM('Oriģinālā tāme'!K64,'Oriģinālā tāme'!K69,'Oriģinālā tāme'!K74,'Oriģinālā tāme'!K79) -> 675.8535 | L19: =SUM('Oriģinālā tāme'!L64,'Oriģinālā tāme'!L69,'Oriģinālā tāme'!L74,'Oriģinālā tāme'!L79) -> 1718.5989 | M19: =SUM('Oriģinālā tāme'!M64,'Oriģinālā tāme'!M69,'Oriģinālā tāme'!M74,'Oriģinālā tāme'!M79) -> 154.4808 | N19: =SUM(1975.06,533.49,34.09,6.3) -> 2548.94 | O19: PA1.6; PA1.7; PA1.8; PA1.9
A20: Grupas starpsumma | K20: =SUM(K17:K19) -> 3108.2765 | L20: =SUM(L17:L19) -> 15110.318 | M20: =SUM(M17:M19) -> 1089.7482 | N20: =SUM(N17:N19) -> 19308.36
A22: 4. Betona un Estrich grīdas
A23: 7 | B23: Betona un Estrich grīdas | C23: Sausā betona grīda (vid. 60 mm) | D23: 60 | E23: m2 | F23: =SUM('Oriģinālā tāme'!F41,'Oriģinālā tāme'!F49,'Oriģinālā tāme'!F54,'Oriģinālā tāme'!F76) -> 3161.7 | G23: ='Oriģinālā tāme'!G41 -> 4.05 | H23: ='Oriģinālā tāme'!H41 -> 5.4 | I23: ='Oriģinālā tāme'!I41 -> 1.35 | J23: =SUM(G23:I23) -> 10.8 | K23: =SUM('Oriģinālā tāme'!K41,'Oriģinālā tāme'!K49,'Oriģinālā tāme'!K54,'Oriģinālā tāme'!K76) -> 12804.885 | L23: =SUM('Oriģinālā tāme'!L41,'Oriģinālā tāme'!L49,'Oriģinālā tāme'!L54,'Oriģinālā tāme'!L76) -> 17073.18 | M23: =SUM('Oriģinālā tāme'!M41,'Oriģinālā tāme'!M49,'Oriģinālā tāme'!M54,'Oriģinālā tāme'!M76) -> 4268.295 | N23: =SUM(29641.14,4213.09,240.62,51.52) -> 34146.37 | O23: PA1.1; PA1.3; PA1.4; PA1.9
A24: 8 | B24: Betona un Estrich grīdas | C24: Sausā betona grīda (vid. 85 mm) | D24: 85 | E24: m2 | F24: ='Oriģinālā tāme'!F46 -> 635.92 | G24: ='Oriģinālā tāme'!G46 -> 4.05 | H24: ='Oriģinālā tāme'!H46 -> 7.65 | I24: ='Oriģinālā tāme'!I46 -> 1.35 | J24: =SUM(G24:I24) -> 13.05 | K24: ='Oriģinālā tāme'!K46 -> 2575.476 | L24: ='Oriģinālā tāme'!L46 -> 4864.788 | M24: ='Oriģinālā tāme'!M46 -> 858.492 | N24: =8298.76 -> 8298.76 | O24: PA1.2
A25: 9 | B25: Betona un Estrich grīdas | C25: Sausā betona grīda (vid. 120 mm) | D25: 120 | E25: m2 | F25: ='Oriģinālā tāme'!F59 -> 32.46 | G25: ='Oriģinālā tāme'!G59 -> 4.05 | H25: ='Oriģinālā tāme'!H59 -> 10.8 | I25: ='Oriģinālā tāme'!I59 -> 1.35 | J25: =SUM(G25:I25) -> 16.2 | K25: ='Oriģinālā tāme'!K59 -> 131.463 | L25: ='Oriģinālā tāme'!L59 -> 350.568 | M25: ='Oriģinālā tāme'!M59 -> 43.821 | N25: =525.85 -> 525.85 | O25: PA1.5
A26: 10 | B26: Betona un Estrich grīdas | C26: Sausā betona grīda (vid. 70 mm) | D26: 70 | E26: m2 | F26: ='Oriģinālā tāme'!F61 -> 1496.26 | G26: ='Oriģinālā tāme'!G61 -> 4.05 | H26: ='Oriģinālā tāme'!H61 -> 6.3 | I26: ='Oriģinālā tāme'!I61 -> 1.35 | J26: =SUM(G26:I26) -> 11.7 | K26: ='Oriģinālā tāme'!K61 -> 6059.853 | L26: ='Oriģinālā tāme'!L61 -> 9426.438 | M26: ='Oriģinālā tāme'!M61 -> 2019.951 | N26: =17506.24 -> 17506.24 | O26: PA1.6
A27: 11 | B27: Betona un Estrich grīdas | C27: Sausā betona grīda (vid. 55 mm) | D27: 55 | E27: m2 | F27: ='Oriģinālā tāme'!F66 -> 404.16 | G27: ='Oriģinālā tāme'!G66 -> 4.05 | H27: ='Oriģinālā tāme'!H66 -> 4.95 | I27: ='Oriģinālā tāme'!I66 -> 1.35 | J27: =SUM(G27:I27) -> 10.35 | K27: ='Oriģinālā tāme'!K66 -> 1636.848 | L27: ='Oriģinālā tāme'!L66 -> 2000.592 | M27: ='Oriģinālā tāme'!M66 -> 545.616 | N27: =4183.06 -> 4183.06 | O27: PA1.7
A28: 12 | B28: Betona un Estrich grīdas | C28: Dzelzsbetons C25/30, 75mm, Transportbetons C25/30 ar fibrām 25kg/m3 | D28: 75 | E28: m2 | F28: ='Oriģinālā tāme'!F71 -> 25.82 | G28: ='Oriģinālā tāme'!G71 -> 14.3 | H28: ='Oriģinālā tāme'!H71 -> 33.975 | I28: ='Oriģinālā tāme'!I71 -> 10.375 | J28: =SUM(G28:I28) -> 58.65 | K28: ='Oriģinālā tāme'!K71 -> 369.226 | L28: ='Oriģinālā tāme'!L71 -> 877.2345 | M28: ='Oriģinālā tāme'!M71 -> 267.8825 | N28: =1514.6 -> 1514.6 | O28: PA1.8
A29: Grupas starpsumma | K29: =SUM(K23:K28) -> 23577.751 | L29: =SUM(L23:L28) -> 34592.8 | M29: =SUM(M23:M28) -> 8004.0575 | N29: =SUM(N23:N28) -> 66174.88
A31: DARBU IZMAKSAS KOPĀ | N31: =SUM(N9,N14,N20,N29) -> 156289.7
A32: Virsizdevumi | J32: 0.05 | N32: =ROUND(N31*J32,2) -> 7814.49
A33: PAVISAM KOPĀ | N33: =N31+N32 -> 164104.19
A35: Kontrole pret oriģinālās tāmes darbu izmaksām | N35: =N31-156289.7 -> 0 | O35: 0,00 = sakrīt
A38: Sākotnējās tāmes piezīmes un nosacījumi
A39: Pasūtītājam jānodrošina tekošs ūdens, Transporta un virsizdevumi 0.05 7814.49
A40: 220 V un 380 V elektrības pieslēgums. Kopā (Bez PVN): 164104.19
A41: Piedāvājumā nav iekļautas pozīcijas, kurās nav norādītas izmaksas
A42: Telpām jābūt atbrīvotām un pamatnei attīrītai.
A43: Telpās jābūt nodrošinātai gaisa temperatūrai vismaz +5 grādi bez caurvēja.
A44: Gala norēķins tiek veikts pēc faktiskā apjoma.
A45: Piedāvājums spēkā 30 dienas no tā sagatavošanas dienas.
A46: Sastādīja: Gundars Starovoitovs
A47: Tālr. +371 29483838
A48: info@thermowhite.lv
A49: www.thermowhite.lv
...

Sheet Oriģinālā tāme
A1: Cenu piedāvājums Nr.G 033 V/26 I
G3: Datums: 16.06.2026
A6: OBJEKTS: Šmerļa ielā 3a, Rīgā.
A8: Npk | B8: Kods | C8: Darbu un izdevumu nosaukums | D8: Biezums | E8: Mērv. | F8: Daudz. | G8: Vienības cena | J8: Vienības cena | K8: Kopā | N8: Summa EUR
D9: mm | G9: Darbs | H9: Materiāli | I9: Mehānismi | K9: Darbs | L9: Materiāli | M9: Mehānismi
J10: 0 | K10: 0 | L10: 0 | M10: 0 | N10: 0
A11: =N84 -> 164104.19 | C11: Transportbetons
C12: Betonēšana ar Transportbetonu C30/37 | D12: 100 | E12: m2 | F12: 250 | G12: 6.51 | H12: 130 | I12: 3.85 | J12: =I12+H12+G12 -> 140.36
C13: Betonēšana ar Transportbetonu C30/37 metāla fibras 25 kg/m3 | D13: 100 | E13: m2 | F13: 250 | G13: 7.15 | H13: 151 | I13: 4.15 | J13: =I13+H13+G13 -> 162.3
C14: Virsmas apstrāde ar cietinātāju Mapei AR6 | E14: m2 | F14: 250 | G14: 0.85 | H14: 2.34 | I14: 0.09 | J14: =I14+H14+G14 -> 3.28
C15: Armatūras sieta D5x150x150 uzstādīšana vienā kārtā uz distanceriem 30mm | E15: m2 | F15: 250 | G15: 2.64 | I15: 0.37 | J15: =I15+H15+G15 -> 3.01
C16: Šuvju zāģēšana 6x6m un šuvju aizpildīšana ar poliuritāna hermētiķi Penosil, iekļauta sagatavošana, atdures uzstādīšāna, aizpildīšana) šuves platumam līdz 15mm | D16: 0.45 no m2 | E16: m | F16: =F13*0.45 -> 112.5 | G16: 3.34 | H16: 3.25 | I16: 1.25 | J16: =I16+H16+G16 -> 7.84
C17: Siltā grīda
C18: silto grīdu cauruļu Herz PE-RT 16mm montāža, solis 150mm | E18: m2 | F18: 217.6 | G18: 4.85 | H18: 6.73 | I18: 1.38 | J18: =I18+H18+G18 -> 12.96
C19: kolektors Herz, cauruļu pievienošana, spiediena ielaišana sistēmā | E19: kpl. | F19: 1 | G19: 110 | H19: 558.62 | I19: 15 | J19: =I19+H19+G19 -> 683.62
C20: Kolektora dekoratīvā skapja uzstādīšana | E20: kpl. | F20: 1 | G20: 35 | H20: 160.32 | I20: 5.23 | J20: =I20+H20+G20 -> 200.55
C21: Linolejs | J21: =I21+H21+G21 -> 0 | K21: =G21*F21 -> 0 | L21: =H21*F21 -> 0 | M21: =I21*F21 -> 0 | N21: =M21+L21+K21 -> 0
C22: tīrīšana,gruntēšana,špaktelēšana(1-2mm),slīpēšana | E22: m2 | F22: 100 | G22: 4.03 | H22: 2.3 | I22: 0.58 | J22: =I22+H22+G22 -> 6.91
C23: pašizlīdzinošais 10mm | E23: m2 | F23: 100 | G23: 6.61 | H23: 10.54 | I23: 1.44 | J23: =I23+H23+G23 -> 18.59
C24: Linolejs bez uzlocījuma | E24: m2 | F24: 100 | G24: 8.9 | H24: 2.19 | I24: 1.69 | J24: =I24+H24+G24 -> 12.78
C25: Linolejs ar uzlocijumu 100mm | E25: m2 | F25: 100 | G25: 14.95 | H25: 2.19 | I25: 1.73 | J25: =I25+H25+G25 -> 18.87
C26: paklāja ielīmēšana | E26: m2 | F26: 100 | G26: 9.63 | H26: 2.19 | I26: 0.69 | J26: =I26+H26+G26 -> 12.51
C27: paklājflīzes montāža | E27: m2 | F27: 100 | G27: 7.67 | H27: 2.01 | I27: 0.69 | J27: =I27+H27+G27 -> 10.37
C28: gumijas ruļļu ielīmēšana | E28: m2 | F28: 100 | G28: 10.35 | H28: 2.19 | I28: 0.69 | J28: =I28+H28+G28 -> 13.23
C29: Mākslīgās zāles ielīmēšana | E29: m2 | F29: 100 | G29: 9.2 | H29: 2.19 | I29: 0.69 | J29: =I29+H29+G29 -> 12.08
C30: grīdlīstes montāža | E30: m | F30: 100 | G30: 5.75 | H30: 1.15 | I30: 0.98 | J30: =I30+H30+G30 -> 7.88
C31: vinila dēļu vai flīžu ielīmēšana | E31: m2 | F31: 100 | G31: 8.05 | H31: 1.73 | I31: 0.69 | J31: =I31+H31+G31 -> 10.47
C32: Krāsojums ar Tonētu epoksīdsveķu krāsu divas reizes | E32: m2 | G32: 16.56 | H32: 17.65 | I32: 4.95 | J32: =I32+H32+G32 -> 39.16 | K32: =G32*F32 -> 0 | L32: =H32*F32 -> 0 | M32: =I32*F32 -> 0 | N32: =M32+L32+K32 -> 0
C33: Ekstrudētais putupolitirols XPS, vai EPS200-250 | E33: m2 | G33: 2.05 | H33: 120 | I33: 0.25 | J33: =I33+H33+G33 -> 122.3
A34: =N84 -> 164104.19 | C34: WD100R m3 cena | D34: ja 30-50mm tad cena augstāka | G34: 38.5 | H34: 115 | I34: 22.5 | J34: =I34+H34+G34 -> 176
C35: WD130R m3 cena | G35: 38.5 | H35: 132.5 | I35: 22.5 | J35: =I35+H35+G35 -> 193.5
C36: Betona klons Estrich ar polipropilēna disperso armējumu 0.9kg/m3 | E36: m2 | G36: 4.05 | H36: 90 | I36: 1.35 | J36: =I36+H36+G36 -> 95.4
C37: PVC Plēve | E37: m2 | G37: 0.35 | H37: 0.89 | I37: 0.08 | J37: =I37+H37+G37 -> 1.32
C38: PE5/300 | E38: m2 | G38: 0.35 | H38: 4.55 | I38: 0.08 | J38: =I38+H38+G38 -> 4.98
C39: Tracker paklājs | G39: 0.35 | H39: 3.54 | I39: 0.08 | J39: =I39+H39+G39 -> 3.97
C40: PA1.1 | J40: =I40+H40+G40 -> 0 | K40: =G40*F40 -> 0 | L40: =H40*F40 -> 0 | M40: =I40*F40 -> 0 | N40: =M40+L40+K40 -> 0
A41: 1 | C41: Sausā betona grīda, 65-58mm | D41: 60 | E41: m2 | F41: 2744.55 | G41: =$G$36 -> 4.05 | H41: =$H$36*D41/1000 -> 5.4 | I41: =$I$36 -> 1.35 | J41: =I41+H41+G41 -> 10.8 | K41: =G41*F41 -> 11115.43 | L41: =H41*F41 -> 14820.57 | M41: =I41*F41 -> 3705.14 | N41: =M41+L41+K41 -> 29641.14
A42: =+A41+1 -> 2 | C42: ThermoWhite, 53-30mm, Thermowhite WD100R | D42: 45 | E42: m2 | F42: =+F41 -> 2744.55 | G42: =$G$34*D42/1000 -> 1.73 | H42: =$H$34*D42/1000 -> 5.18 | I42: =$I$34*D42/1000 -> 1.01 | J42: =I42+H42+G42 -> 7.92 | K42: =G42*F42 -> 4748.07 | L42: =H42*F42 -> 14216.77 | M42: =I42*F42 -> 2772 | N42: =M42+L42+K42 -> 21736.84
A43: =+A42+1 -> 3 | C43: PEPI Trafo 7 putu polietilēna plēve, 7mm | E43: m2 | F43: =+F42 -> 2744.55 | G43: 0.35 | H43: 2.79 | I43: 0.18 | J43: =I43+H43+G43 -> 3.32 | K43: =G43*F43 -> 960.59 | L43: =H43*F43 -> 7657.29 | M43: =I43*F43 -> 494.02 | N43: =M43+L43+K43 -> 9111.9
A44: =+A43+1 -> 4 | C44: Plēve, atbilstoši thermowhite system | E44: m2 | F44: =+F43 -> 2744.55 | G44: =$G$37 -> 0.35 | H44: =$H$37 -> 0.89 | I44: =$I$37 -> 0.08 | J44: =I44+H44+G44 -> 1.32 | K44: =G44*F44 -> 960.59 | L44: =H44*F44 -> 2442.65 | M44: =I44*F44 -> 219.56 | N44: =M44+L44+K44 -> 3622.8
...
