Workbook

Sheet Kopsavilkums
A1: WhatsApp 2026 → WorksRecorded pirmsimporta pārskats
A2: Organizācija: 58467603-196e-4661-83ff-fe26e4b0ff0b | Avots saglabāts un nekas nav importēts.
A4: Piedāvātie ieraksti | B4: =COUNTA('Vietņu ieraksti'!A5:A493) -> 489 | D4: Projekti | E4: =COUNTA(Projekti!A5:A130) -> 126 | G4: Kopā m² | H4: =SUM('Vietņu ieraksti'!H5:H493) -> 78535.28
A5: Jāpārskata | B5: =COUNTA(Pārskatīšana!A5:A213) -> 209 | D5: Ar multividi | E5: =SUMPRODUCT(--(LEN('Vietņu ieraksti'!R5:R493)>0)) -> 181 | G5: Avota ziņas | H5: =COUNTA('Avota ziņas'!A5:A663) -> 659
A7: Mēnesis | B7: Ieraksti | C7: Kopā m² | D7: Jāpārskata | E7: Ar multividi
A8: janvāris | B8: =COUNTIFS('Vietņu ieraksti'!B5:B493,">="&DATE(2026,1,1),'Vietņu ieraksti'!B5:B493,"<"&DATE(2026,2,1)) -> 37 | C8: =SUMIFS('Vietņu ieraksti'!H5:H493,'Vietņu ieraksti'!B5:B493,">="&DATE(2026,1,1),'Vietņu ieraksti'!B5:B493,"<"&DATE(2026,2,1)) -> 7570 | D8: =COUNTIFS(Pārskatīšana!B5:B213,">="&DATE(2026,1,1),Pārskatīšana!B5:B213,"<"&DATE(2026,2,1)) -> 6 | E8: =SUMPRODUCT(--('Vietņu ieraksti'!B5:B493>=DATE(2026,1,1)),--('Vietņu ieraksti'!B5:B493<DATE(2026,2,1)),--(LEN('Vietņu ieraksti'!R5:R493)>0)) -> 4
A9: februāris | B9: =COUNTIFS('Vietņu ieraksti'!B5:B493,">="&DATE(2026,2,1),'Vietņu ieraksti'!B5:B493,"<"&DATE(2026,3,1)) -> 100 | C9: =SUMIFS('Vietņu ieraksti'!H5:H493,'Vietņu ieraksti'!B5:B493,">="&DATE(2026,2,1),'Vietņu ieraksti'!B5:B493,"<"&DATE(2026,3,1)) -> 19010 | D9: =COUNTIFS(Pārskatīšana!B5:B213,">="&DATE(2026,2,1),Pārskatīšana!B5:B213,"<"&DATE(2026,3,1)) -> 45 | E9: =SUMPRODUCT(--('Vietņu ieraksti'!B5:B493>=DATE(2026,2,1)),--('Vietņu ieraksti'!B5:B493<DATE(2026,3,1)),--(LEN('Vietņu ieraksti'!R5:R493)>0)) -> 70
A10: marts | B10: =COUNTIFS('Vietņu ieraksti'!B5:B493,">="&DATE(2026,3,1),'Vietņu ieraksti'!B5:B493,"<"&DATE(2026,4,1)) -> 85 | C10: =SUMIFS('Vietņu ieraksti'!H5:H493,'Vietņu ieraksti'!B5:B493,">="&DATE(2026,3,1),'Vietņu ieraksti'!B5:B493,"<"&DATE(2026,4,1)) -> 16887 | D10: =COUNTIFS(Pārskatīšana!B5:B213,">="&DATE(2026,3,1),Pārskatīšana!B5:B213,"<"&DATE(2026,4,1)) -> 30 | E10: =SUMPRODUCT(--('Vietņu ieraksti'!B5:B493>=DATE(2026,3,1)),--('Vietņu ieraksti'!B5:B493<DATE(2026,4,1)),--(LEN('Vietņu ieraksti'!R5:R493)>0)) -> 44
A11: aprīlis | B11: =COUNTIFS('Vietņu ieraksti'!B5:B493,">="&DATE(2026,4,1),'Vietņu ieraksti'!B5:B493,"<"&DATE(2026,5,1)) -> 67 | C11: =SUMIFS('Vietņu ieraksti'!H5:H493,'Vietņu ieraksti'!B5:B493,">="&DATE(2026,4,1),'Vietņu ieraksti'!B5:B493,"<"&DATE(2026,5,1)) -> 9869 | D11: =COUNTIFS(Pārskatīšana!B5:B213,">="&DATE(2026,4,1),Pārskatīšana!B5:B213,"<"&DATE(2026,5,1)) -> 31 | E11: =SUMPRODUCT(--('Vietņu ieraksti'!B5:B493>=DATE(2026,4,1)),--('Vietņu ieraksti'!B5:B493<DATE(2026,5,1)),--(LEN('Vietņu ieraksti'!R5:R493)>0)) -> 25
A12: maijs | B12: =COUNTIFS('Vietņu ieraksti'!B5:B493,">="&DATE(2026,5,1),'Vietņu ieraksti'!B5:B493,"<"&DATE(2026,6,1)) -> 65 | C12: =SUMIFS('Vietņu ieraksti'!H5:H493,'Vietņu ieraksti'!B5:B493,">="&DATE(2026,5,1),'Vietņu ieraksti'!B5:B493,"<"&DATE(2026,6,1)) -> 7552.28 | D12: =COUNTIFS(Pārskatīšana!B5:B213,">="&DATE(2026,5,1),Pārskatīšana!B5:B213,"<"&DATE(2026,6,1)) -> 27 | E12: =SUMPRODUCT(--('Vietņu ieraksti'!B5:B493>=DATE(2026,5,1)),--('Vietņu ieraksti'!B5:B493<DATE(2026,6,1)),--(LEN('Vietņu ieraksti'!R5:R493)>0)) -> 15
A13: jūnijs | B13: =COUNTIFS('Vietņu ieraksti'!B5:B493,">="&DATE(2026,6,1),'Vietņu ieraksti'!B5:B493,"<"&DATE(2026,7,1)) -> 38 | C13: =SUMIFS('Vietņu ieraksti'!H5:H493,'Vietņu ieraksti'!B5:B493,">="&DATE(2026,6,1),'Vietņu ieraksti'!B5:B493,"<"&DATE(2026,7,1)) -> 5466 | D13: =COUNTIFS(Pārskatīšana!B5:B213,">="&DATE(2026,6,1),Pārskatīšana!B5:B213,"<"&DATE(2026,7,1)) -> 17 | E13: =SUMPRODUCT(--('Vietņu ieraksti'!B5:B493>=DATE(2026,6,1)),--('Vietņu ieraksti'!B5:B493<DATE(2026,7,1)),--(LEN('Vietņu ieraksti'!R5:R493)>0)) -> 7
A14: jūlijs | B14: =COUNTIFS('Vietņu ieraksti'!B5:B493,">="&DATE(2026,7,1),'Vietņu ieraksti'!B5:B493,"<"&DATE(2026,8,1)) -> 43 | C14: =SUMIFS('Vietņu ieraksti'!H5:H493,'Vietņu ieraksti'!B5:B493,">="&DATE(2026,7,1),'Vietņu ieraksti'!B5:B493,"<"&DATE(2026,8,1)) -> 4335 | D14: =COUNTIFS(Pārskatīšana!B5:B213,">="&DATE(2026,7,1),Pārskatīšana!B5:B213,"<"&DATE(2026,8,1)) -> 25 | E14: =SUMPRODUCT(--('Vietņu ieraksti'!B5:B493>=DATE(2026,7,1)),--('Vietņu ieraksti'!B5:B493<DATE(2026,8,1)),--(LEN('Vietņu ieraksti'!R5:R493)>0)) -> 6
A15: augusts | B15: =COUNTIFS('Vietņu ieraksti'!B5:B493,">="&DATE(2026,8,1),'Vietņu ieraksti'!B5:B493,"<"&DATE(2026,9,1)) -> 51 | C15: =SUMIFS('Vietņu ieraksti'!H5:H493,'Vietņu ieraksti'!B5:B493,">="&DATE(2026,8,1),'Vietņu ieraksti'!B5:B493,"<"&DATE(2026,9,1)) -> 7521 | D15: =COUNTIFS(Pārskatīšana!B5:B213,">="&DATE(2026,8,1),Pārskatīšana!B5:B213,"<"&DATE(2026,9,1)) -> 27 | E15: =SUMPRODUCT(--('Vietņu ieraksti'!B5:B493>=DATE(2026,8,1)),--('Vietņu ieraksti'!B5:B493<DATE(2026,9,1)),--(LEN('Vietņu ieraksti'!R5:R493)>0)) -> 8
A16: septembris | B16: =COUNTIFS('Vietņu ieraksti'!B5:B493,">="&DATE(2026,9,1),'Vietņu ieraksti'!B5:B493,"<"&DATE(2026,10,1)) -> 3 | C16: =SUMIFS('Vietņu ieraksti'!H5:H493,'Vietņu ieraksti'!B5:B493,">="&DATE(2026,9,1),'Vietņu ieraksti'!B5:B493,"<"&DATE(2026,10,1)) -> 325 | D16: =COUNTIFS(Pārskatīšana!B5:B213,">="&DATE(2026,9,1),Pārskatīšana!B5:B213,"<"&DATE(2026,10,1)) -> 1 | E16: =SUMPRODUCT(--('Vietņu ieraksti'!B5:B493>=DATE(2026,9,1)),--('Vietņu ieraksti'!B5:B493<DATE(2026,10,1)),--(LEN('Vietņu ieraksti'!R5:R493)>0)) -> 2
A17: oktobris | B17: =COUNTIFS('Vietņu ieraksti'!B5:B493,">="&DATE(2026,10,1),'Vietņu ieraksti'!B5:B493,"<"&DATE(2026,11,1)) -> 0 | C17: =SUMIFS('Vietņu ieraksti'!H5:H493,'Vietņu ieraksti'!B5:B493,">="&DATE(2026,10,1),'Vietņu ieraksti'!B5:B493,"<"&DATE(2026,11,1)) -> 0 | D17: =COUNTIFS(Pārskatīšana!B5:B213,">="&DATE(2026,10,1),Pārskatīšana!B5:B213,"<"&DATE(2026,11,1)) -> 0 | E17: =SUMPRODUCT(--('Vietņu ieraksti'!B5:B493>=DATE(2026,10,1)),--('Vietņu ieraksti'!B5:B493<DATE(2026,11,1)),--(LEN('Vietņu ieraksti'!R5:R493)>0)) -> 0
A18: novembris | B18: =COUNTIFS('Vietņu ieraksti'!B5:B493,">="&DATE(2026,11,1),'Vietņu ieraksti'!B5:B493,"<"&DATE(2026,12,1)) -> 0 | C18: =SUMIFS('Vietņu ieraksti'!H5:H493,'Vietņu ieraksti'!B5:B493,">="&DATE(2026,11,1),'Vietņu ieraksti'!B5:B493,"<"&DATE(2026,12,1)) -> 0 | D18: =COUNTIFS(Pārskatīšana!B5:B213,">="&DATE(2026,11,1),Pārskatīšana!B5:B213,"<"&DATE(2026,12,1)) -> 0 | E18: =SUMPRODUCT(--('Vietņu ieraksti'!B5:B493>=DATE(2026,11,1)),--('Vietņu ieraksti'!B5:B493<DATE(2026,12,1)),--(LEN('Vietņu ieraksti'!R5:R493)>0)) -> 0
A19: decembris | B19: =COUNTIFS('Vietņu ieraksti'!B5:B493,">="&DATE(2026,12,1),'Vietņu ieraksti'!B5:B493,"<"&DATE(2027,1,1)) -> 0 | C19: =SUMIFS('Vietņu ieraksti'!H5:H493,'Vietņu ieraksti'!B5:B493,">="&DATE(2026,12,1),'Vietņu ieraksti'!B5:B493,"<"&DATE(2027,1,1)) -> 0 | D19: =COUNTIFS(Pārskatīšana!B5:B213,">="&DATE(2026,12,1),Pārskatīšana!B5:B213,"<"&DATE(2027,1,1)) -> 0 | E19: =SUMPRODUCT(--('Vietņu ieraksti'!B5:B493>=DATE(2026,12,1)),--('Vietņu ieraksti'!B5:B493<DATE(2027,1,1)),--(LEN('Vietņu ieraksti'!R5:R493)>0)) -> 0
A21: Pārliecība | B21: Ieraksti
A22: Augsta | B22: =COUNTIF('Vietņu ieraksti'!T5:T493,A22) -> 280
A23: Vidēja | B23: =COUNTIF('Vietņu ieraksti'!T5:T493,A23) -> 159
A24: Zema | B24: =COUNTIF('Vietņu ieraksti'!T5:T493,A24) -> 50

Sheet Projekti
A1: 2026. gada projekti un nosaukumu grupējums
A2: Pārbaudiet aliasus un WorksRecorded atbilstību. Projekta nosaukums nav automātiski izveidots sistēmā.
A4: Projekts | B4: Avota nosaukumi / aliasi | C4: Ieraksti | D4: Kopā m² | E4: Pirmais datums | F4: Pēdējais datums | G4: Jāpārskata | H4: Ar multividi | I4: Esošs WorksRecorded projekts | J4: Darbība pirms importa
A5: Uriekstes iela 42B | B5: Uiriekstes iela 42B | Uriekstes 42B | Uriekstes iela | Uriekstes iela 42 B | Uriekstes iela 42B | C5: =COUNTIF('Vietņu ieraksti'!E5:E493,A5) -> 56 | D5: =SUMIF('Vietņu ieraksti'!E5:E493,A5,'Vietņu ieraksti'!H5:H493) -> 8019 | E5: =_xlfn.MINIFS('Vietņu ieraksti'!B5:B493,'Vietņu ieraksti'!E5:E493,A5) -> 46090 | F5: =_xlfn.MAXIFS('Vietņu ieraksti'!B5:B493,'Vietņu ieraksti'!E5:E493,A5) -> 46204 | G5: =COUNTIF(Pārskatīšana!C5:C213,A5) -> 19 | H5: =SUMPRODUCT(--('Vietņu ieraksti'!E5:E493=A5),--(LEN('Vietņu ieraksti'!R5:R493)>0)) -> 26 | J5: Apstiprināt / izveidot
A6: Barona iela 119 | B6: Barona | Barona iela | Barona iela 119 | Barona iela veselības centrs | Barona iela119 | C6: =COUNTIF('Vietņu ieraksti'!E5:E493,A6) -> 41 | D6: =SUMIF('Vietņu ieraksti'!E5:E493,A6,'Vietņu ieraksti'!H5:H493) -> 7726 | E6: =_xlfn.MINIFS('Vietņu ieraksti'!B5:B493,'Vietņu ieraksti'!E5:E493,A6) -> 46027 | F6: =_xlfn.MAXIFS('Vietņu ieraksti'!B5:B493,'Vietņu ieraksti'!E5:E493,A6) -> 46114 | G6: =COUNTIF(Pārskatīšana!C5:C213,A6) -> 14 | H6: =SUMPRODUCT(--('Vietņu ieraksti'!E5:E493=A6),--(LEN('Vietņu ieraksti'!R5:R493)>0)) -> 24 | J6: Apstiprināt / izveidot
A7: Dārzciema iela 86 | B7: Dārzciema iela 86 | Dārzciema ielā 86 | C7: =COUNTIF('Vietņu ieraksti'!E5:E493,A7) -> 39 | D7: =SUMIF('Vietņu ieraksti'!E5:E493,A7,'Vietņu ieraksti'!H5:H493) -> 7830 | E7: =_xlfn.MINIFS('Vietņu ieraksti'!B5:B493,'Vietņu ieraksti'!E5:E493,A7) -> 46057 | F7: =_xlfn.MAXIFS('Vietņu ieraksti'!B5:B493,'Vietņu ieraksti'!E5:E493,A7) -> 46144 | G7: =COUNTIF(Pārskatīšana!C5:C213,A7) -> 16 | H7: =SUMPRODUCT(--('Vietņu ieraksti'!E5:E493=A7),--(LEN('Vietņu ieraksti'!R5:R493)>0)) -> 34 | J7: Apstiprināt / izveidot
A8: Spilves 27 | B8: Spilvas iela 27 | Spilves 27 | Spilves iela | Spilves iela 27 | Spilves ielas koridors | C8: =COUNTIF('Vietņu ieraksti'!E5:E493,A8) -> 35 | D8: =SUMIF('Vietņu ieraksti'!E5:E493,A8,'Vietņu ieraksti'!H5:H493) -> 5380 | E8: =_xlfn.MINIFS('Vietņu ieraksti'!B5:B493,'Vietņu ieraksti'!E5:E493,A8) -> 46175 | F8: =_xlfn.MAXIFS('Vietņu ieraksti'!B5:B493,'Vietņu ieraksti'!E5:E493,A8) -> 46265 | G8: =COUNTIF(Pārskatīšana!C5:C213,A8) -> 20 | H8: =SUMPRODUCT(--('Vietņu ieraksti'!E5:E493=A8),--(LEN('Vietņu ieraksti'!R5:R493)>0)) -> 1 | I8: Spilves 27 | J8: Piesaistīt esošajam
A9: Jānosaka projekts | B9: -24.03 Alūksne, Ziemeru 4 | *17.04*, *18.04*, *20.04*, *21.04* | 59 lime | C9: =COUNTIF('Vietņu ieraksti'!E5:E493,A9) -> 32 | D9: =SUMIF('Vietņu ieraksti'!E5:E493,A9,'Vietņu ieraksti'!H5:H493) -> 5482.28 | E9: =_xlfn.MINIFS('Vietņu ieraksti'!B5:B493,'Vietņu ieraksti'!E5:E493,A9) -> 46065 | F9: =_xlfn.MAXIFS('Vietņu ieraksti'!B5:B493,'Vietņu ieraksti'!E5:E493,A9) -> 46253 | G9: =COUNTIF(Pārskatīšana!C5:C213,A9) -> 32 | H9: =SUMPRODUCT(--('Vietņu ieraksti'!E5:E493=A9),--(LEN('Vietņu ieraksti'!R5:R493)>0)) -> 21 | J9: Apstiprināt / izveidot
A10: Krustabaznīcas iela | B10: Krustabaznīcas 11 | Krustabaznīcas 11 estrich, plēve 130m² 53 maisi cements | Krustabaznīcas 11 TW 190m² | Krustbaznīcas iela | Krustbaznīcas iela 11 | C10: =COUNTIF('Vietņu ieraksti'!E5:E493,A10) -> 28 | D10: =SUMIF('Vietņu ieraksti'!E5:E493,A10,'Vietņu ieraksti'!H5:H493) -> 3148 | E10: =_xlfn.MINIFS('Vietņu ieraksti'!B5:B493,'Vietņu ieraksti'!E5:E493,A10) -> 46059 | F10: =_xlfn.MAXIFS('Vietņu ieraksti'!B5:B493,'Vietņu ieraksti'!E5:E493,A10) -> 46192 | G10: =COUNTIF(Pārskatīšana!C5:C213,A10) -> 2 | H10: =SUMPRODUCT(--('Vietņu ieraksti'!E5:E493=A10),--(LEN('Vietņu ieraksti'!R5:R493)>0)) -> 11 | J10: Apstiprināt / izveidot
A11: Bērzaunes iela 15 | B11: Berzaunes 15 Estrich 70m² | Bērzaunes 15 | Bērzaunes iela | Bērzaunes iela 15 | C11: =COUNTIF('Vietņu ieraksti'!E5:E493,A11) -> 23 | D11: =SUMIF('Vietņu ieraksti'!E5:E493,A11,'Vietņu ieraksti'!H5:H493) -> 3030 | E11: =_xlfn.MINIFS('Vietņu ieraksti'!B5:B493,'Vietņu ieraksti'!E5:E493,A11) -> 46036 | F11: =_xlfn.MAXIFS('Vietņu ieraksti'!B5:B493,'Vietņu ieraksti'!E5:E493,A11) -> 46172 | G11: =COUNTIF(Pārskatīšana!C5:C213,A11) -> 3 | H11: =SUMPRODUCT(--('Vietņu ieraksti'!E5:E493=A11),--(LEN('Vietņu ieraksti'!R5:R493)>0)) -> 1 | J11: Apstiprināt / izveidot
A12: Balasta dambis 2 | B12: Balasta dambis | Balasta dambis 2 | Balasta iela | Balasta iela 2 | C12: =COUNTIF('Vietņu ieraksti'!E5:E493,A12) -> 11 | D12: =SUMIF('Vietņu ieraksti'!E5:E493,A12,'Vietņu ieraksti'!H5:H493) -> 70 | E12: =_xlfn.MINIFS('Vietņu ieraksti'!B5:B493,'Vietņu ieraksti'!E5:E493,A12) -> 46219 | F12: =_xlfn.MAXIFS('Vietņu ieraksti'!B5:B493,'Vietņu ieraksti'!E5:E493,A12) -> 46266 | G12: =COUNTIF(Pārskatīšana!C5:C213,A12) -> 11 | H12: =SUMPRODUCT(--('Vietņu ieraksti'!E5:E493=A12),--(LEN('Vietņu ieraksti'!R5:R493)>0)) -> 0 | I12: Balasta dambis 2 | J12: Piesaistīt esošajam
A13: Raiņa iela 2A, Iecava | B13: Iecava Raiņa iela | Iecava, Raiņa iela 2A | Raiņa iela 2, Iecava | Raiņa iela 2A, Iecava | C13: =COUNTIF('Vietņu ieraksti'!E5:E493,A13) -> 10 | D13: =SUMIF('Vietņu ieraksti'!E5:E493,A13,'Vietņu ieraksti'!H5:H493) -> 2020 | E13: =_xlfn.MINIFS('Vietņu ieraksti'!B5:B493,'Vietņu ieraksti'!E5:E493,A13) -> 46031 | F13: =_xlfn.MAXIFS('Vietņu ieraksti'!B5:B493,'Vietņu ieraksti'!E5:E493,A13) -> 46068 | G13: =COUNTIF(Pārskatīšana!C5:C213,A13) -> 1 | H13: =SUMPRODUCT(--('Vietņu ieraksti'!E5:E493=A13),--(LEN('Vietņu ieraksti'!R5:R493)>0)) -> 4 | J13: Apstiprināt / izveidot
A14: Kadaga | B14: Kadaga | C14: =COUNTIF('Vietņu ieraksti'!E5:E493,A14) -> 8 | D14: =SUMIF('Vietņu ieraksti'!E5:E493,A14,'Vietņu ieraksti'!H5:H493) -> 2592 | E14: =_xlfn.MINIFS('Vietņu ieraksti'!B5:B493,'Vietņu ieraksti'!E5:E493,A14) -> 46030 | F14: =_xlfn.MAXIFS('Vietņu ieraksti'!B5:B493,'Vietņu ieraksti'!E5:E493,A14) -> 46074 | G14: =COUNTIF(Pārskatīšana!C5:C213,A14) -> 1 | H14: =SUMPRODUCT(--('Vietņu ieraksti'!E5:E493=A14),--(LEN('Vietņu ieraksti'!R5:R493)>0)) -> 0 | J14: Apstiprināt / izveidot
A15: VC4 | B15: *VC4, B119.* | Expons VC4 | VC4 | VC4, 6.st | VC4, B119 | VC4, B119, pagrabs | C15: =COUNTIF('Vietņu ieraksti'!E5:E493,A15) -> 8 | D15: =SUMIF('Vietņu ieraksti'!E5:E493,A15,'Vietņu ieraksti'!H5:H493) -> 528 | E15: =_xlfn.MINIFS('Vietņu ieraksti'!B5:B493,'Vietņu ieraksti'!E5:E493,A15) -> 46036 | F15: =_xlfn.MAXIFS('Vietņu ieraksti'!B5:B493,'Vietņu ieraksti'!E5:E493,A15) -> 46174 | G15: =COUNTIF(Pārskatīšana!C5:C213,A15) -> 6 | H15: =SUMPRODUCT(--('Vietņu ieraksti'!E5:E493=A15),--(LEN('Vietņu ieraksti'!R5:R493)>0)) -> 3 | J15: Apstiprināt / izveidot
A16: Čaka iela 123 | B16: Čaka iela 123 | C16: =COUNTIF('Vietņu ieraksti'!E5:E493,A16) -> 7 | D16: =SUMIF('Vietņu ieraksti'!E5:E493,A16,'Vietņu ieraksti'!H5:H493) -> 1018 | E16: =_xlfn.MINIFS('Vietņu ieraksti'!B5:B493,'Vietņu ieraksti'!E5:E493,A16) -> 46132 | F16: =_xlfn.MAXIFS('Vietņu ieraksti'!B5:B493,'Vietņu ieraksti'!E5:E493,A16) -> 46174 | G16: =COUNTIF(Pārskatīšana!C5:C213,A16) -> 3 | H16: =SUMPRODUCT(--('Vietņu ieraksti'!E5:E493=A16),--(LEN('Vietņu ieraksti'!R5:R493)>0)) -> 2 | J16: Apstiprināt / izveidot
A17: Dzirciema iela 16 | B17: Dzirciema 16, RSU (720m2) | Dzirciema 16, RSU (720m2~) | Dzirciema iela 16 | C17: =COUNTIF('Vietņu ieraksti'!E5:E493,A17) -> 5 | D17: =SUMIF('Vietņu ieraksti'!E5:E493,A17,'Vietņu ieraksti'!H5:H493) -> 2700 | E17: =_xlfn.MINIFS('Vietņu ieraksti'!B5:B493,'Vietņu ieraksti'!E5:E493,A17) -> 46027 | F17: =_xlfn.MAXIFS('Vietņu ieraksti'!B5:B493,'Vietņu ieraksti'!E5:E493,A17) -> 46094 | G17: =COUNTIF(Pārskatīšana!C5:C213,A17) -> 1 | H17: =SUMPRODUCT(--('Vietņu ieraksti'!E5:E493=A17),--(LEN('Vietņu ieraksti'!R5:R493)>0)) -> 3 | J17: Apstiprināt / izveidot
A18: Gaiļezera slimnīca | B18: Gaiļezera slimnīca | C18: =COUNTIF('Vietņu ieraksti'!E5:E493,A18) -> 5 | D18: =SUMIF('Vietņu ieraksti'!E5:E493,A18,'Vietņu ieraksti'!H5:H493) -> 886 | E18: =_xlfn.MINIFS('Vietņu ieraksti'!B5:B493,'Vietņu ieraksti'!E5:E493,A18) -> 46231 | F18: =_xlfn.MAXIFS('Vietņu ieraksti'!B5:B493,'Vietņu ieraksti'!E5:E493,A18) -> 46255 | G18: =COUNTIF(Pārskatīšana!C5:C213,A18) -> 0 | H18: =SUMPRODUCT(--('Vietņu ieraksti'!E5:E493=A18),--(LEN('Vietņu ieraksti'!R5:R493)>0)) -> 0 | J18: Apstiprināt / izveidot
A19: Prohorova iela 13 | B19: Prohorova iela 13 | C19: =COUNTIF('Vietņu ieraksti'!E5:E493,A19) -> 5 | D19: =SUMIF('Vietņu ieraksti'!E5:E493,A19,'Vietņu ieraksti'!H5:H493) -> 1599 | E19: =_xlfn.MINIFS('Vietņu ieraksti'!B5:B493,'Vietņu ieraksti'!E5:E493,A19) -> 46119 | F19: =_xlfn.MAXIFS('Vietņu ieraksti'!B5:B493,'Vietņu ieraksti'!E5:E493,A19) -> 46135 | G19: =COUNTIF(Pārskatīšana!C5:C213,A19) -> 2 | H19: =SUMPRODUCT(--('Vietņu ieraksti'!E5:E493=A19),--(LEN('Vietņu ieraksti'!R5:R493)>0)) -> 3 | J19: Apstiprināt / izveidot
A20: Vairāki objekti — jāsadala | B20: Objekts | C20: =COUNTIF('Vietņu ieraksti'!E5:E493,A20) -> 5 | D20: =SUMIF('Vietņu ieraksti'!E5:E493,A20,'Vietņu ieraksti'!H5:H493) -> 211 | E20: =_xlfn.MINIFS('Vietņu ieraksti'!B5:B493,'Vietņu ieraksti'!E5:E493,A20) -> 46156 | F20: =_xlfn.MAXIFS('Vietņu ieraksti'!B5:B493,'Vietņu ieraksti'!E5:E493,A20) -> 46161 | G20: =COUNTIF(Pārskatīšana!C5:C213,A20) -> 5 | H20: =SUMPRODUCT(--('Vietņu ieraksti'!E5:E493=A20),--(LEN('Vietņu ieraksti'!R5:R493)>0)) -> 0 | J20: Apstiprināt / izveidot
A21: "Rozītes", Daugmales pagasts, ķekavas novads | B21: "Rozītes", Daugmales pagasts, ķekavas novads | C21: =COUNTIF('Vietņu ieraksti'!E5:E493,A21) -> 6 | D21: =SUMIF('Vietņu ieraksti'!E5:E493,A21,'Vietņu ieraksti'!H5:H493) -> 1509 | E21: =_xlfn.MINIFS('Vietņu ieraksti'!B5:B493,'Vietņu ieraksti'!E5:E493,A21) -> 46232 | F21: =_xlfn.MAXIFS('Vietņu ieraksti'!B5:B493,'Vietņu ieraksti'!E5:E493,A21) -> 46264 | G21: =COUNTIF(Pārskatīšana!C5:C213,A21) -> 0 | H21: =SUMPRODUCT(--('Vietņu ieraksti'!E5:E493=A21),--(LEN('Vietņu ieraksti'!R5:R493)>0)) -> 2 | J21: Apstiprināt / izveidot
A22: Augusta Saulieša iela 14 Cesvaine | B22: Augusta Saulieša iela 14 Cesvaine | C22: =COUNTIF('Vietņu ieraksti'!E5:E493,A22) -> 4 | D22: =SUMIF('Vietņu ieraksti'!E5:E493,A22,'Vietņu ieraksti'!H5:H493) -> 1090 | E22: =_xlfn.MINIFS('Vietņu ieraksti'!B5:B493,'Vietņu ieraksti'!E5:E493,A22) -> 46128 | F22: =_xlfn.MAXIFS('Vietņu ieraksti'!B5:B493,'Vietņu ieraksti'!E5:E493,A22) -> 46149 | G22: =COUNTIF(Pārskatīšana!C5:C213,A22) -> 0 | H22: =SUMPRODUCT(--('Vietņu ieraksti'!E5:E493=A22),--(LEN('Vietņu ieraksti'!R5:R493)>0)) -> 0 | J22: Apstiprināt / izveidot
A23: Jelgava, pasta iela 63 | B23: Jelgava, pasta iela 63 | C23: =COUNTIF('Vietņu ieraksti'!E5:E493,A23) -> 4 | D23: =SUMIF('Vietņu ieraksti'!E5:E493,A23,'Vietņu ieraksti'!H5:H493) -> 705 | E23: =_xlfn.MINIFS('Vietņu ieraksti'!B5:B493,'Vietņu ieraksti'!E5:E493,A23) -> 46069 | F23: =_xlfn.MAXIFS('Vietņu ieraksti'!B5:B493,'Vietņu ieraksti'!E5:E493,A23) -> 46097 | G23: =COUNTIF(Pārskatīšana!C5:C213,A23) -> 0 | H23: =SUMPRODUCT(--('Vietņu ieraksti'!E5:E493=A23),--(LEN('Vietņu ieraksti'!R5:R493)>0)) -> 0 | J23: Apstiprināt / izveidot
A24: Krasta iela 6 Lubāna | B24: Krasta iela 6 Lubāna | C24: =COUNTIF('Vietņu ieraksti'!E5:E493,A24) -> 4 | D24: =SUMIF('Vietņu ieraksti'!E5:E493,A24,'Vietņu ieraksti'!H5:H493) -> 805 | E24: =_xlfn.MINIFS('Vietņu ieraksti'!B5:B493,'Vietņu ieraksti'!E5:E493,A24) -> 46072 | F24: =_xlfn.MAXIFS('Vietņu ieraksti'!B5:B493,'Vietņu ieraksti'!E5:E493,A24) -> 46076 | G24: =COUNTIF(Pārskatīšana!C5:C213,A24) -> 0 | H24: =SUMPRODUCT(--('Vietņu ieraksti'!E5:E493=A24),--(LEN('Vietņu ieraksti'!R5:R493)>0)) -> 4 | J24: Apstiprināt / izveidot
A25: No 23.03 lidz 27.03 | B25: No 23.03 lidz 27.03 | C25: =COUNTIF('Vietņu ieraksti'!E5:E493,A25) -> 4 | D25: =SUMIF('Vietņu ieraksti'!E5:E493,A25,'Vietņu ieraksti'!H5:H493) -> 948 | E25: =_xlfn.MINIFS('Vietņu ieraksti'!B5:B493,'Vietņu ieraksti'!E5:E493,A25) -> 46108 | F25: =_xlfn.MAXIFS('Vietņu ieraksti'!B5:B493,'Vietņu ieraksti'!E5:E493,A25) -> 46108 | G25: =COUNTIF(Pārskatīšana!C5:C213,A25) -> 0 | H25: =SUMPRODUCT(--('Vietņu ieraksti'!E5:E493=A25),--(LEN('Vietņu ieraksti'!R5:R493)>0)) -> 4 | J25: Apstiprināt / izveidot
A26: Bukultu iela 7k1 | B26: Bukultu iela 7k1 | C26: =COUNTIF('Vietņu ieraksti'!E5:E493,A26) -> 3 | D26: =SUMIF('Vietņu ieraksti'!E5:E493,A26,'Vietņu ieraksti'!H5:H493) -> 640 | E26: =_xlfn.MINIFS('Vietņu ieraksti'!B5:B493,'Vietņu ieraksti'!E5:E493,A26) -> 46122 | F26: =_xlfn.MAXIFS('Vietņu ieraksti'!B5:B493,'Vietņu ieraksti'!E5:E493,A26) -> 46141 | G26: =COUNTIF(Pārskatīšana!C5:C213,A26) -> 3 | H26: =SUMPRODUCT(--('Vietņu ieraksti'!E5:E493=A26),--(LEN('Vietņu ieraksti'!R5:R493)>0)) -> 2 | J26: Apstiprināt / izveidot
A27: Čaka 123 | B27: Čaka 123 | C27: =COUNTIF('Vietņu ieraksti'!E5:E493,A27) -> 3 | D27: =SUMIF('Vietņu ieraksti'!E5:E493,A27,'Vietņu ieraksti'!H5:H493) -> 700 | E27: =_xlfn.MINIFS('Vietņu ieraksti'!B5:B493,'Vietņu ieraksti'!E5:E493,A27) -> 46142 | F27: =_xlfn.MAXIFS('Vietņu ieraksti'!B5:B493,'Vietņu ieraksti'!E5:E493,A27) -> 46169 | G27: =COUNTIF(Pārskatīšana!C5:C213,A27) -> 1 | H27: =SUMPRODUCT(--('Vietņu ieraksti'!E5:E493=A27),--(LEN('Vietņu ieraksti'!R5:R493)>0)) -> 2 | J27: Apstiprināt / izveidot
A28: Dārciema iela | B28: Dārciema iela | C28: =COUNTIF('Vietņu ieraksti'!E5:E493,A28) -> 3 | D28: =SUMIF('Vietņu ieraksti'!E5:E493,A28,'Vietņu ieraksti'!H5:H493) -> 501 | E28: =_xlfn.MINIFS('Vietņu ieraksti'!B5:B493,'Vietņu ieraksti'!E5:E493,A28) -> 46056 | F28: =_xlfn.MAXIFS('Vietņu ieraksti'!B5:B493,'Vietņu ieraksti'!E5:E493,A28) -> 46098 | G28: =COUNTIF(Pārskatīšana!C5:C213,A28) -> 2 | H28: =SUMPRODUCT(--('Vietņu ieraksti'!E5:E493=A28),--(LEN('Vietņu ieraksti'!R5:R493)>0)) -> 0 | J28: Apstiprināt / izveidot
A29: Dārzciema iela | B29: Dārzciema iela | C29: =COUNTIF('Vietņu ieraksti'!E5:E493,A29) -> 3 | D29: =SUMIF('Vietņu ieraksti'!E5:E493,A29,'Vietņu ieraksti'!H5:H493) -> 1039 | E29: =_xlfn.MINIFS('Vietņu ieraksti'!B5:B493,'Vietņu ieraksti'!E5:E493,A29) -> 46063 | F29: =_xlfn.MAXIFS('Vietņu ieraksti'!B5:B493,'Vietņu ieraksti'!E5:E493,A29) -> 46085 | G29: =COUNTIF(Pārskatīšana!C5:C213,A29) -> 2 | H29: =SUMPRODUCT(--('Vietņu ieraksti'!E5:E493=A29),--(LEN('Vietņu ieraksti'!R5:R493)>0)) -> 0 | J29: Apstiprināt / izveidot
A30: Jaunolaine meža iela 2 | B30: Jaunolaine meža iela 2 | C30: =COUNTIF('Vietņu ieraksti'!E5:E493,A30) -> 3 | D30: =SUMIF('Vietņu ieraksti'!E5:E493,A30,'Vietņu ieraksti'!H5:H493) -> 914 | E30: =_xlfn.MINIFS('Vietņu ieraksti'!B5:B493,'Vietņu ieraksti'!E5:E493,A30) -> 46169 | F30: =_xlfn.MAXIFS('Vietņu ieraksti'!B5:B493,'Vietņu ieraksti'!E5:E493,A30) -> 46171 | G30: =COUNTIF(Pārskatīšana!C5:C213,A30) -> 0 | H30: =SUMPRODUCT(--('Vietņu ieraksti'!E5:E493=A30),--(LEN('Vietņu ieraksti'!R5:R493)>0)) -> 0 | J30: Apstiprināt / izveidot
A31: Kadaga DEPO | B31: *Kadaga DEPO* | Kadaga DEPO | C31: =COUNTIF('Vietņu ieraksti'!E5:E493,A31) -> 3 | D31: =SUMIF('Vietņu ieraksti'!E5:E493,A31,'Vietņu ieraksti'!H5:H493) -> 0 | E31: =_xlfn.MINIFS('Vietņu ieraksti'!B5:B493,'Vietņu ieraksti'!E5:E493,A31) -> 46028 | F31: =_xlfn.MAXIFS('Vietņu ieraksti'!B5:B493,'Vietņu ieraksti'!E5:E493,A31) -> 46162 | G31: =COUNTIF(Pārskatīšana!C5:C213,A31) -> 3 | H31: =SUMPRODUCT(--('Vietņu ieraksti'!E5:E493=A31),--(LEN('Vietņu ieraksti'!R5:R493)>0)) -> 1 | J31: Apstiprināt / izveidot
A32: Meža iela 2 Jaunolaine | B32: Meža iela 2 Jaunolaine | C32: =COUNTIF('Vietņu ieraksti'!E5:E493,A32) -> 3 | D32: =SUMIF('Vietņu ieraksti'!E5:E493,A32,'Vietņu ieraksti'!H5:H493) -> 860 | E32: =_xlfn.MINIFS('Vietņu ieraksti'!B5:B493,'Vietņu ieraksti'!E5:E493,A32) -> 46153 | F32: =_xlfn.MAXIFS('Vietņu ieraksti'!B5:B493,'Vietņu ieraksti'!E5:E493,A32) -> 46155 | G32: =COUNTIF(Pārskatīšana!C5:C213,A32) -> 0 | H32: =SUMPRODUCT(--('Vietņu ieraksti'!E5:E493=A32),--(LEN('Vietņu ieraksti'!R5:R493)>0)) -> 3 | J32: Apstiprināt / izveidot
A33: Meža iela2, Jaunolaine | B33: Meža iela2, Jaunolaine | C33: =COUNTIF('Vietņu ieraksti'!E5:E493,A33) -> 3 | D33: =SUMIF('Vietņu ieraksti'!E5:E493,A33,'Vietņu ieraksti'!H5:H493) -> 998 | E33: =_xlfn.MINIFS('Vietņu ieraksti'!B5:B493,'Vietņu ieraksti'!E5:E493,A33) -> 46176 | F33: =_xlfn.MAXIFS('Vietņu ieraksti'!B5:B493,'Vietņu ieraksti'!E5:E493,A33) -> 46182 | G33: =COUNTIF(Pārskatīšana!C5:C213,A33) -> 0 | H33: =SUMPRODUCT(--('Vietņu ieraksti'!E5:E493=A33),--(LEN('Vietņu ieraksti'!R5:R493)>0)) -> 3 | J33: Apstiprināt / izveidot
A34: Preses nama kvartāls | B34: Preses nama kvartāls | C34: =COUNTIF('Vietņu ieraksti'!E5:E493,A34) -> 3 | D34: =SUMIF('Vietņu ieraksti'!E5:E493,A34,'Vietņu ieraksti'!H5:H493) -> 184 | E34: =_xlfn.MINIFS('Vietņu ieraksti'!B5:B493,'Vietņu ieraksti'!E5:E493,A34) -> 46228 | F34: =_xlfn.MAXIFS('Vietņu ieraksti'!B5:B493,'Vietņu ieraksti'!E5:E493,A34) -> 46248 | G34: =COUNTIF(Pārskatīšana!C5:C213,A34) -> 1 | H34: =SUMPRODUCT(--('Vietņu ieraksti'!E5:E493=A34),--(LEN('Vietņu ieraksti'!R5:R493)>0)) -> 0 | J34: Apstiprināt / izveidot
A35: Prohorova iela 13, Jelgava | B35: Prohorova iela 13, Jelgava | C35: =COUNTIF('Vietņu ieraksti'!E5:E493,A35) -> 3 | D35: =SUMIF('Vietņu ieraksti'!E5:E493,A35,'Vietņu ieraksti'!H5:H493) -> 846 | E35: =_xlfn.MINIFS('Vietņu ieraksti'!B5:B493,'Vietņu ieraksti'!E5:E493,A35) -> 46093 | F35: =_xlfn.MAXIFS('Vietņu ieraksti'!B5:B493,'Vietņu ieraksti'!E5:E493,A35) -> 46194 | G35: =COUNTIF(Pārskatīšana!C5:C213,A35) -> 3 | H35: =SUMPRODUCT(--('Vietņu ieraksti'!E5:E493=A35),--(LEN('Vietņu ieraksti'!R5:R493)>0)) -> 3 | J35: Apstiprināt / izveidot
A36: Sarkanmuižas dambis1, Ventspils | B36: Sarkanmuižas dambis1, Ventspils | C36: =COUNTIF('Vietņu ieraksti'!E5:E493,A36) -> 3 | D36: =SUMIF('Vietņu ieraksti'!E5:E493,A36,'Vietņu ieraksti'!H5:H493) -> 447 | E36: =_xlfn.MINIFS('Vietņu ieraksti'!B5:B493,'Vietņu ieraksti'!E5:E493,A36) -> 46210 | F36: =_xlfn.MAXIFS('Vietņu ieraksti'!B5:B493,'Vietņu ieraksti'!E5:E493,A36) -> 46210 | G36: =COUNTIF(Pārskatīšana!C5:C213,A36) -> 3 | H36: =SUMPRODUCT(--('Vietņu ieraksti'!E5:E493=A36),--(LEN('Vietņu ieraksti'!R5:R493)>0)) -> 3 | J36: Apstiprināt / izveidot
A37: Stabu iela 6-11A | B37: Stabu iela 6-11A | C37: =COUNTIF('Vietņu ieraksti'!E5:E493,A37) -> 3 | D37: =SUMIF('Vietņu ieraksti'!E5:E493,A37,'Vietņu ieraksti'!H5:H493) -> 134 | E37: =_xlfn.MINIFS('Vietņu ieraksti'!B5:B493,'Vietņu ieraksti'!E5:E493,A37) -> 46085 | F37: =_xlfn.MAXIFS('Vietņu ieraksti'!B5:B493,'Vietņu ieraksti'!E5:E493,A37) -> 46087 | G37: =COUNTIF(Pārskatīšana!C5:C213,A37) -> 2 | H37: =SUMPRODUCT(--('Vietņu ieraksti'!E5:E493=A37),--(LEN('Vietņu ieraksti'!R5:R493)>0)) -> 0 | J37: Apstiprināt / izveidot
A38: Šmerļa iela 3 | B38: Šmerļa iela 3 | C38: =COUNTIF('Vietņu ieraksti'!E5:E493,A38) -> 3 | D38: =SUMIF('Vietņu ieraksti'!E5:E493,A38,'Vietņu ieraksti'!H5:H493) -> 435 | E38: =_xlfn.MINIFS('Vietņu ieraksti'!B5:B493,'Vietņu ieraksti'!E5:E493,A38) -> 46265 | F38: =_xlfn.MAXIFS('Vietņu ieraksti'!B5:B493,'Vietņu ieraksti'!E5:E493,A38) -> 46266 | G38: =COUNTIF(Pārskatīšana!C5:C213,A38) -> 0 | H38: =SUMPRODUCT(--('Vietņu ieraksti'!E5:E493=A38),--(LEN('Vietņu ieraksti'!R5:R493)>0)) -> 2 | I38: Šmerļa iela 3 | J38: Piesaistīt esošajam
A39: Urieksetes iela 42B | B39: Urieksetes iela 42B | C39: =COUNTIF('Vietņu ieraksti'!E5:E493,A39) -> 3 | D39: =SUMIF('Vietņu ieraksti'!E5:E493,A39,'Vietņu ieraksti'!H5:H493) -> 131 | E39: =_xlfn.MINIFS('Vietņu ieraksti'!B5:B493,'Vietņu ieraksti'!E5:E493,A39) -> 46185 | F39: =_xlfn.MAXIFS('Vietņu ieraksti'!B5:B493,'Vietņu ieraksti'!E5:E493,A39) -> 46185 | G39: =COUNTIF(Pārskatīšana!C5:C213,A39) -> 0 | H39: =SUMPRODUCT(--('Vietņu ieraksti'!E5:E493=A39),--(LEN('Vietņu ieraksti'!R5:R493)>0)) -> 0 | J39: Apstiprināt / izveidot
A40: "Rozītes", Daugmales pagasts, Ķekavas novads | B40: "Rozītes", Daugmales pagasts, Ķekavas novads | C40: =COUNTIF('Vietņu ieraksti'!E5:E493,A40) -> 6 | D40: =SUMIF('Vietņu ieraksti'!E5:E493,A40,'Vietņu ieraksti'!H5:H493) -> 1509 | E40: =_xlfn.MINIFS('Vietņu ieraksti'!B5:B493,'Vietņu ieraksti'!E5:E493,A40) -> 46232 | F40: =_xlfn.MAXIFS('Vietņu ieraksti'!B5:B493,'Vietņu ieraksti'!E5:E493,A40) -> 46264 | G40: =COUNTIF(Pārskatīšana!C5:C213,A40) -> 0 | H40: =SUMPRODUCT(--('Vietņu ieraksti'!E5:E493=A40),--(LEN('Vietņu ieraksti'!R5:R493)>0)) -> 2 | J40: Apstiprināt / izveidot
A41: *Jelgava, Prohorova 13* | B41: *Jelgava, Prohorova 13* | C41: =COUNTIF('Vietņu ieraksti'!E5:E493,A41) -> 2 | D41: =SUMIF('Vietņu ieraksti'!E5:E493,A41,'Vietņu ieraksti'!H5:H493) -> 200 | E41: =_xlfn.MINIFS('Vietņu ieraksti'!B5:B493,'Vietņu ieraksti'!E5:E493,A41) -> 46165 | F41: =_xlfn.MAXIFS('Vietņu ieraksti'!B5:B493,'Vietņu ieraksti'!E5:E493,A41) -> 46165 | G41: =COUNTIF(Pārskatīšana!C5:C213,A41) -> 2 | H41: =SUMPRODUCT(--('Vietņu ieraksti'!E5:E493=A41),--(LEN('Vietņu ieraksti'!R5:R493)>0)) -> 0 | J41: Apstiprināt / izveidot
...

Sheet Vietņu ieraksti
A1: 2026. gada piedāvātie vietņu dienasgrāmatas ieraksti
A2: Avots: WhatsApp eksports. Automātiska pirmsimporta sagatave — 489 rindas; nekas nav augšupielādēts WorksRecorded.
A4: Ieraksta ID | B4: Darba datums | C4: Ziņas datums | D4: Laiks | E4: Projekts — normalizēts | F4: Projekts — avotā | G4: Darba veids | H4: Apjoms m² | I4: Biezums no, mm | J4: Biezums līdz, mm | K4: Stāvs / zona | L4: Cements, maisi | M4: Līme, vien. | N4: Plēve, ruļļi | O4: Granulas, vien. | P4: Materiāli / detaļas | Q4: Autors | R4: Multivides faili | S4: Avota ziņa | T4: Pārliecība | U4: Pārskatīšanas statuss | V4: Pārskatīšanas iemesls | W4: Avota ziņas Nr. | X4: Importa darbība
A5: WR-2026-0001 | B5: 46027 | C5: 46027 | D5: 18:08:59 | E5: Barona iela 119 | F5: Barona iela 119 | G5: Thermowhite | H5: 235 | M5: 49 | Q5: Ronalds Gatavotājs TW Pumpists | S5: Barona iela 119 235 m2 49 līmes 05.01.26. | T5: Augsta | U5: Gatavs pārbaudei | W5: 275 | X5: Iekļaut
A6: WR-2026-0002 | B6: 46027 | C6: 46027 | D6: 17:13:45 | E6: Dzirciema iela 16 | F6: Dzirciema iela 16 | G6: Thermowhite | H6: 300 | M6: 69 | Q6: Dāvis Estrich Limeni Jaunā Brigāde | S6: Dzirciema iela 16, Rīga 300m2 Thermo 69maisi līme 05.01.2026 | T6: Augsta | U6: Gatavs pārbaudei | W6: 274 | X6: Iekļaut
A7: WR-2026-0003 | B7: 46028 | C7: 46028 | D7: 18:20:05 | E7: Barona iela 119 | F7: Barona iela 119 | G7: Thermowhite | H7: 293 | M7: 69 | Q7: Ronalds Gatavotājs TW Pumpists | S7: Barona iela 119 293 m2 69 līmes 06.01.26 | T7: Augsta | U7: Gatavs pārbaudei | W7: 278 | X7: Iekļaut
A8: WR-2026-0004 | B8: 46028 | C8: 46028 | D8: 15:48:27 | E8: Kadaga DEPO | F8: Kadaga DEPO | G8: Šuvju aizpildīšana | P8: PENOSIL 8GB + SILKA 4GB | Q8: Edijs Vinvalks | S8: Kadaga DEPO - Visa platība aizpildītas šuves starp pamatni un sienām + kāpnes PENOSIL 8GB + SILKA 4GB 06.01.2026 | T8: Vidēja | U8: Pārbaudīt | V8: Nav norādīts m² apjoms | W8: 276 | X8: Pārskatīt
A9: WR-2026-0005 | B9: 46028 | C9: 46028 | D9: 16:53:44 | E9: Vēžu iela 4, Roja | F9: Roja Vēžu iela 4 | G9: Thermowhite | H9: 113 | M9: 34 | P9: TW 113m² 34 līmes un granulas | Q9: Artis Expon Briško | S9: Roja Vēžu iela 4 TW 113m² 34 līmes un granulas | T9: Augsta | U9: Gatavs pārbaudei | W9: 277 | X9: Iekļaut
A10: WR-2026-0006 | B10: 46029 | C10: 46030 | D10: 11:43:13 | E10: Barona iela 119 | F10: Barona | G10: Thermowhite | H10: 224 | M10: 69 | Q10: Ronalds Gatavotājs TW Pumpists | S10: Barona 224m2 69 līmes 07.01.26 | T10: Augsta | U10: Gatavs pārbaudei | W10: 280 | X10: Iekļaut
A11: WR-2026-0007 | B11: 46029 | C11: 46029 | D11: 16:02:12 | E11: Dzirciema iela 16 | F11: Dzirciema iela 16 | G11: Estrich | H11: 240 | L11: 60 | Q11: Dāvis Estrich Limeni Jaunā Brigāde | S11: Dzirciema iela 16, Rīga 240m2 estrich + plēve 60 maisi cements 7.1.26 <This message was edited> | T11: Vidēja | U11: Pārbaudīt | V11: Ziņa ir rediģēta | W11: 279 | X11: Pārskatīt
A12: WR-2026-0008 | B12: 46030 | C12: 46030 | D12: 20:56:41 | E12: Kadaga | F12: Kadaga | G12: Thermowhite | H12: 360 | M12: 73 | Q12: Ronalds Gatavotājs TW Pumpists | S12: Kadaga 360 m2 73 līmes 08.01.26 | T12: Augsta | U12: Gatavs pārbaudei | W12: 281 | X12: Iekļaut
A13: WR-2026-0009 | B13: 46031 | C13: 46031 | D13: 20:04:00 | E13: Raiņa iela 2A, Iecava | F13: Iecava Raiņa iela | G13: Thermowhite | H13: 400 | M13: 134 | Q13: Ronalds Gatavotājs TW Pumpists | S13: Iecava Raiņa iela 400m2 134 līmēs 09.01.26. | T13: Augsta | U13: Gatavs pārbaudei | W13: 282 | X13: Iekļaut
A14: WR-2026-0010 | B14: 46034 | C14: 46034 | D14: 19:03:45 | E14: Barona iela 119 | F14: Barona iela | G14: Thermowhite | H14: 212 | M14: 70 | Q14: Ronalds Gatavotājs TW Pumpists | S14: Barona iela 212 m2 70 līmes 12.01.26 | T14: Augsta | U14: Gatavs pārbaudei | W14: 283 | X14: Iekļaut
A15: WR-2026-0011 | B15: 46035 | C15: 46035 | D15: 19:48:02 | E15: Barona iela 119 | F15: Barona iela | G15: Thermowhite | H15: 390 | M15: 109 | Q15: Ronalds Gatavotājs TW Pumpists | S15: Barona iela 390 m2 109 līmes 13.01.26 | T15: Augsta | U15: Gatavs pārbaudei | W15: 286 | X15: Iekļaut
A16: WR-2026-0012 | B16: 46035 | C16: 46035 | D16: 19:03:24 | E16: Raiņa iela 2A, Iecava | F16: Raiņa iela 2A, Iecava | G16: Estrich | H16: 206 | L16: 90 | N16: 4 | Q16: Dāvis Estrich Limeni Jaunā Brigāde | S16: Raiņa iela 2A, Iecava 206m2 estrich + plēve 4x ruļļi + cements 90 maisi 13.01.26 | T16: Augsta | U16: Gatavs pārbaudei | W16: 285 | X16: Iekļaut
A17: WR-2026-0013 | B17: 46036 | C17: 46036 | D17: 17:50:14 | E17: Bērzaunes iela 15 | F17: Bērzaunes iela | G17: Thermowhite | H17: 256 | M17: 40 | Q17: Ronalds Gatavotājs TW Pumpists | S17: Bērzaunes iela 256m2 40 līmes 14.01.26 | T17: Augsta | U17: Gatavs pārbaudei | W17: 290 | X17: Iekļaut
A18: WR-2026-0014 | B18: 46036 | C18: 46036 | D18: 17:52:15 | E18: VC4 | F18: Expons VC4 | G18: Jānosaka darba veids | H18: 120 | I18: 100 | J18: 100 | K18: 5st | Q18: Limeni! | S18: Expons VC4 5st. 120m2 100mm (16:15) | T18: Vidēja | U18: Pārbaudīt | V18: Darba veids nav skaidrs | W18: 291 | X18: Pārskatīt
A19: WR-2026-0015 | B19: 46037 | C19: 46037 | D19: 17:36:55 | E19: Barona iela 119 | F19: Barona iela 119 | G19: Estrich | H19: 100 | L19: 35 | Q19: Dāvis Estrich Limeni Jaunā Brigāde | S19: Barona iela 119 100m2 estrich 35maisi cements 15.01.26 | T19: Augsta | U19: Gatavs pārbaudei | W19: 294 | X19: Iekļaut
A20: WR-2026-0016 | B20: 46037 | C20: 46037 | D20: 16:23:08 | E20: Bērzaunes iela 15 | F20: Bērzaunes iela | G20: Thermowhite | H20: 117 | M20: 29 | Q20: Ronalds Gatavotājs TW Pumpists | S20: Bērzaunes iela 117 m2 29 līmes 15.01.26 | T20: Augsta | U20: Gatavs pārbaudei | W20: 293 | X20: Iekļaut
A21: WR-2026-0017 | B21: 46037 | C21: 46037 | D21: 14:01:15 | E21: VC4 | F21: VC4 | G21: Plēves ieklāšana | H21: 400 | K21: 6st | N21: 8 | Q21: Edijs Vinvalks | S21: VC4 - 6st. 400m2 plēve (8 ruļļi) | T21: Augsta | U21: Gatavs pārbaudei | W21: 292 | X21: Iekļaut
A22: WR-2026-0018 | B22: 46038 | C22: 46038 | D22: 20:00:17 | E22: Kadaga | F22: Kadaga | G22: Thermowhite | H22: 377 | M22: 97 | Q22: Ronalds Gatavotājs TW Pumpists | S22: Kadaga 377m2 97 līmes 16.01.26. | T22: Augsta | U22: Gatavs pārbaudei | W22: 295 | X22: Iekļaut
A23: WR-2026-0019 | B23: 46041 | C23: 46042 | D23: 07:21:25 | E23: Kadaga | F23: Kadaga | G23: Thermowhite | H23: 347 | M23: 87 | Q23: Ronalds Gatavotājs TW Pumpists | S23: Kadaga 347 m2 87 līmes 19.01.26 | T23: Augsta | U23: Gatavs pārbaudei | W23: 296 | X23: Iekļaut
A24: WR-2026-0020 | B24: 46042 | C24: 46043 | D24: 08:02:45 | E24: Kadaga | F24: Kadaga | G24: Thermowhite | H24: 274 | M24: 66 | Q24: Ronalds Gatavotājs TW Pumpists | S24: Kadaga 274 m2 66 līmes 20.01.26. | T24: Augsta | U24: Gatavs pārbaudei | W24: 298 | X24: Iekļaut
A25: WR-2026-0021 | B25: 46044 | C25: 46044 | D25: 18:26:30 | E25: Barona iela 119 | F25: Barona iela 119 | G25: Estrich | H25: 155 | L25: 65 | Q25: Dāvis Estrich Limeni Jaunā Brigāde | R25: 00000307-PHOTO-2026-01-22-18-26-30.jpg | S25: Barona iela 119 6.st. 155m2 estrich 65maisi cements 22.01.26 <attached: 00000307-PHOTO-2026-01-22-18-26-30.jpg> | T25: Augsta | U25: Gatavs pārbaudei | W25: 307 | X25: Iekļaut
A26: WR-2026-0022 | B26: 46044 | C26: 46044 | D26: 15:46:46 | E26: Bērzaunes iela 15 | F26: Bērzaunes 15 | G26: Estrich | H26: 90 | Q26: Artis Expon Briško | S26: Bērzaunes 15 Estrich 90m² | T26: Augsta | U26: Gatavs pārbaudei | W26: 306 | X26: Iekļaut
A27: WR-2026-0023 | B27: 46045 | C27: 46045 | D27: 20:44:14 | E27: Barona iela 119 | F27: Barona iela 119 | G27: Estrich | H27: 160 | L27: 70 | Q27: Dāvis Estrich Limeni Jaunā Brigāde | R27: 00000310-PHOTO-2026-01-23-20-44-14.jpg | S27: Barona iela 119 6.st. 160m2 estrich 70 maisi cements 23.01.26 <attached: 00000310-PHOTO-2026-01-23-20-44-14.jpg> | T27: Augsta | U27: Gatavs pārbaudei | W27: 310 | X27: Iekļaut
A28: WR-2026-0024 | B28: 46045 | C28: 46045 | D28: 20:44:15 | E28: Barona iela 119 | F28: Barona iela 119 | G28: Estrich | H28: 160 | L28: 70 | Q28: Dāvis Estrich Limeni Jaunā Brigāde | R28: 00000311-PHOTO-2026-01-23-20-44-15.jpg | S28: Barona iela 119 6.st. 160m2 estrich 70 maisi cements 23.01.26 <attached: 00000311-PHOTO-2026-01-23-20-44-15.jpg> | T28: Vidēja | U28: Pārbaudīt | V28: Iespējams dublikāts avota ziņai Nr. 310 | W28: 311 | X28: Pārskatīt
A29: WR-2026-0025 | B29: 46045 | C29: 46045 | D29: 16:04:47 | E29: Bērzaunes iela 15 | F29: Bērzaunes 15 | G29: Estrich | H29: 102 | Q29: Artis Expon Briško | S29: Bērzaunes 15 Estrich 102m² | T29: Augsta | U29: Gatavs pārbaudei | W29: 308 | X29: Iekļaut
A30: WR-2026-0026 | B30: 46045 | C30: 46045 | D30: 18:37:23 | E30: Raiņa iela 2A, Iecava | F30: Iecava Raiņa iela | G30: Thermowhite | M30: 170 | Q30: Ronalds Gatavotājs TW Pumpists | S30: Iecava Raiņa iela 400 170 līmes 23.01.26 | T30: Vidēja | U30: Pārbaudīt | V30: Nav norādīts m² apjoms | W30: 309 | X30: Pārskatīt
A31: WR-2026-0027 | B31: 46046 | C31: 46046 | D31: 21:25:36 | E31: Barona iela 119 | F31: Barona iela 119 | G31: Estrich | H31: 107 | L31: 51 | Q31: Granulas 8eur/gab. | R31: 00000312-PHOTO-2026-01-24-21-25-36.jpg | S31: Barona iela 119 5.st 107m2 Estrich 51maisi cements 24.01.2026 <attached: 00000312-PHOTO-2026-01-24-21-25-36.jpg> | T31: Augsta | U31: Gatavs pārbaudei | W31: 312 | X31: Iekļaut
A32: WR-2026-0028 | B32: 46048 | C32: 46048 | D32: 15:07:26 | E32: Bērzaunes iela 15 | F32: Bērzaunes 15 | G32: Estrich | H32: 113 | Q32: Artis Expon Briško | S32: Bērzaunes 15 Estrich 113m² | T32: Augsta | U32: Gatavs pārbaudei | W32: 313 | X32: Iekļaut
A33: WR-2026-0029 | B33: 46048 | C33: 46048 | D33: 21:09:34 | E33: Kadaga | F33: Kadaga | G33: Thermowhite | H33: 279 | M33: 49 | Q33: Ronalds Gatavotājs TW Pumpists | S33: Kadaga 279 m2 49 līmes 26.01.26 | T33: Augsta | U33: Gatavs pārbaudei | W33: 314 | X33: Iekļaut
A34: WR-2026-0030 | B34: 46050 | C34: 46050 | D34: 20:03:29 | E34: Bērzaunes iela 15 | F34: Berzaunes 15 Estrich 70m² | G34: Estrich | H34: 70 | Q34: Artis Expon Briško | S34: 27.01. Berzaunes 15 Estrich 70m² 28.01. Dārza 10b Estrich 70m² | T34: Augsta | U34: Gatavs pārbaudei | W34: 317 | X34: Iekļaut
A35: WR-2026-0031 | B35: 46050 | C35: 46050 | D35: 20:03:29 | E35: Bērzaunes iela 15 | F35: Berzaunes 15 Estrich 70m² | G35: Estrich | H35: 70 | Q35: Artis Expon Briško | S35: 27.01. Berzaunes 15 Estrich 70m² 28.01. Dārza 10b Estrich 70m² | T35: Augsta | U35: Gatavs pārbaudei | W35: 317 | X35: Iekļaut
A36: WR-2026-0032 | B36: 46050 | C36: 46050 | D36: 19:46:31 | E36: Jūrmalas gatve 51 | F36: Jūrmalas gatve 51 | G36: Thermowhite | M36: 28 | Q36: Ronalds Gatavotājs TW Pumpists | S36: Jūrmalas gatve 51 28 līmes 28.01.26 | T36: Vidēja | U36: Pārbaudīt | V36: Nav norādīts m² apjoms | W36: 316 | X36: Pārskatīt
A37: WR-2026-0033 | B37: 46050 | C37: 46050 | D37: 14:53:13 | E37: Raiņa iela 2A, Iecava | F37: Iecava, Raiņa iela 2A | G37: Estrich | H37: 290 | L37: 85 | Q37: Dāvis Estrich Limeni Jaunā Brigāde | S37: Iecava, Raiņa iela 2A 290m2 estrich + plēve 85maisi cements 27.01. - 28.01. | T37: Augsta | U37: Gatavs pārbaudei | W37: 315 | X37: Iekļaut
A38: WR-2026-0034 | B38: 46051 | C38: 46051 | D38: 20:35:45 | E38: Kadaga | F38: Kadaga | G38: Thermowhite | H38: 331 | M38: 77 | Q38: Ronalds Gatavotājs TW Pumpists | S38: Kadaga 331 m2 77 līmes 29.01.26 | T38: Augsta | U38: Gatavs pārbaudei | W38: 319 | X38: Iekļaut
A39: WR-2026-0035 | B39: 46051 | C39: 46051 | D39: 13:52:48 | E39: Raiņa iela 2A, Iecava | F39: Iecava, Raiņa iela 2A | G39: Estrich | H39: 110 | L39: 30 | Q39: Dāvis Estrich Limeni Jaunā Brigāde | S39: Iecava, Raiņa iela 2A 110m2 estrich + plēve 30 maisi cements 29.01 | T39: Augsta | U39: Gatavs pārbaudei | W39: 318 | X39: Iekļaut
A40: WR-2026-0036 | B40: 46052 | C40: 46052 | D40: 17:44:25 | E40: Kadaga | F40: Kadaga | G40: Thermowhite | H40: 264 | M40: 68 | Q40: Ronalds Gatavotājs TW Pumpists | S40: Kadaga 264 m2 68 līmes. 30.01.26 Objekts pabeigts. | T40: Augsta | U40: Gatavs pārbaudei | W40: 320 | X40: Iekļaut
A41: WR-2026-0037 | B41: 46053 | C41: 46053 | D41: 18:31:34 | E41: Barona iela 119 | F41: Barona iela | G41: Thermowhite | H41: 305 | M41: 94 | Q41: Ronalds Gatavotājs TW Pumpists | S41: Barona iela 305 m2 94 līmes 31.01.26. | T41: Augsta | U41: Gatavs pārbaudei | W41: 321 | X41: Iekļaut
...

Sheet Pārskatīšana
A1: Ieraksti, kuri jāpārbauda pirms importa
A2: Šeit ir tikai zemākas pārliecības, rediģētas, neskaidra datuma/projekta vai ar laika tuvumu piesaistītas multivides rindas.
A4: Ieraksta ID | B4: Darba datums | C4: Projekts | D4: Darba veids | E4: Apjoms m² | F4: Pārliecība | G4: Iemesls | H4: Autors | I4: Multivide | J4: Avota ziņa | K4: Importa darbība
A5: WR-2026-0004 | B5: 46028 | C5: Kadaga DEPO | D5: Šuvju aizpildīšana | F5: Vidēja | G5: Nav norādīts m² apjoms | H5: Edijs Vinvalks | J5: Kadaga DEPO - Visa platība aizpildītas šuves starp pamatni un sienām + kāpnes PENOSIL 8GB + SILKA 4GB 06.01.2026 | K5: Pārskatīt
A6: WR-2026-0007 | B6: 46029 | C6: Dzirciema iela 16 | D6: Estrich | E6: 240 | F6: Vidēja | G6: Ziņa ir rediģēta | H6: Dāvis Estrich Limeni Jaunā Brigāde | J6: Dzirciema iela 16, Rīga 240m2 estrich + plēve 60 maisi cements 7.1.26 <This message was edited> | K6: Pārskatīt
A7: WR-2026-0014 | B7: 46036 | C7: VC4 | D7: Jānosaka darba veids | E7: 120 | F7: Vidēja | G7: Darba veids nav skaidrs | H7: Limeni! | J7: Expons VC4 5st. 120m2 100mm (16:15) | K7: Pārskatīt
A8: WR-2026-0024 | B8: 46045 | C8: Barona iela 119 | D8: Estrich | E8: 160 | F8: Vidēja | G8: Iespējams dublikāts avota ziņai Nr. 310 | H8: Dāvis Estrich Limeni Jaunā Brigāde | I8: 00000311-PHOTO-2026-01-23-20-44-15.jpg | J8: Barona iela 119 6.st. 160m2 estrich 70 maisi cements 23.01.26 <attached: 00000311-PHOTO-2026-01-23-20-44-15.jpg> | K8: Pārskatīt
A9: WR-2026-0026 | B9: 46045 | C9: Raiņa iela 2A, Iecava | D9: Thermowhite | F9: Vidēja | G9: Nav norādīts m² apjoms | H9: Ronalds Gatavotājs TW Pumpists | J9: Iecava Raiņa iela 400 170 līmes 23.01.26 | K9: Pārskatīt
A10: WR-2026-0032 | B10: 46050 | C10: Jūrmalas gatve 51 | D10: Thermowhite | F10: Vidēja | G10: Nav norādīts m² apjoms | H10: Ronalds Gatavotājs TW Pumpists | J10: Jūrmalas gatve 51 28 līmes 28.01.26 | K10: Pārskatīt
A11: WR-2026-0038 | B11: 46055 | C11: Barona iela 119 | D11: Jānosaka darba veids | E11: 203 | F11: Vidēja | G11: Darba veids nav skaidrs | H11: Ronalds Gatavotājs TW Pumpists | J11: Barona iela 203 m2 71 līme 02.02.26. | K11: Pārskatīt
A12: WR-2026-0039 | B12: 46056 | C12: Barona iela 119 | D12: Thermowhite | E12: 343 | F12: Vidēja | G12: Multivide piesaistīta pēc laika tuvuma; Multivide piesaistīta pēc laika tuvuma | H12: Ronalds Gatavotājs TW Pumpists | I12: 00000325-PHOTO-2026-02-03-18-35-59.jpg; 00000326-PHOTO-2026-02-03-18-36-00.jpg | J12: Barona iela 343 m2 76 līmes 03.02.26 | K12: Pārskatīt
A13: WR-2026-0040 | B13: 46056 | C13: Dārciema iela | D13: Thermowhite | E13: 90 | F13: Vidēja | G13: Ziņas un norādītais datums atšķiras par 29 dienām | H13: Ronalds Gatavotājs TW Pumpists | J13: Dārciema iela 17 līmes 90 m2 03.02.26 | K13: Pārskatīt
A14: WR-2026-0042 | B14: 46057 | C14: Dārzciema iela 86 | D14: Thermowhite | E14: 249 | F14: Vidēja | G14: Multivide piesaistīta pēc laika tuvuma; Multivide piesaistīta pēc laika tuvuma | H14: Dāvis Estrich Limeni Jaunā Brigāde | I14: 00000329-PHOTO-2026-02-04-21-36-32.jpg; 00000330-PHOTO-2026-02-04-21-36-32.jpg; 00000331-PHOTO-2026-02-04-21-36-33.jpg | J14: 4. Un 3. Stāvs Dārzciema iela 86 249m2 Thermo 85maisi līme 04.02.26 <attached: 00000329-PHOTO-2026-02-04-21-36-32.jpg> | K14: Pārskatīt
A15: WR-2026-0043 | B15: 46057 | C15: Dārzciema iela 86 | D15: Thermowhite | E15: 249 | F15: Vidēja | G15: Iespējams dublikāts avota ziņai Nr. 329 | H15: Dāvis Estrich Limeni Jaunā Brigāde | I15: 00000332-PHOTO-2026-02-04-21-36-33.jpg | J15: 4. Un 3. Stāvs Dārzciema iela 86 249m2 Thermo 85maisi līme 04.02.26 <attached: 00000332-PHOTO-2026-02-04-21-36-33.jpg> | K15: Pārskatīt
A16: WR-2026-0046 | B16: 46058 | C16: Dārzciema ielā | D16: Jānosaka darba veids | E16: 59 | F16: Vidēja | G16: Darba veids nav skaidrs | H16: Ronalds Gatavotājs TW Pumpists | J16: Dārzciema ielā 33 līm 59m2 + Aizpūtām bedres | K16: Pārskatīt
A17: WR-2026-0053 | B17: 46060 | C17: Barona iela 119 | D17: Estrich | E17: 195 | F17: Vidēja | G17: Multivide piesaistīta pēc laika tuvuma | H17: Granulas 8eur/gab. | I17: 00000342-PHOTO-2026-02-07-21-45-26.jpg; 00000343-PHOTO-2026-02-07-21-45-26.jpg | J17: Barona iela 119 Pagrabs 195m2 Cements 78 07.02.2026 <attached: 00000342-PHOTO-2026-02-07-21-45-26.jpg> | K17: Pārskatīt
A18: WR-2026-0057 | B18: 46063 | C18: Dārzciema iela | D18: Jānosaka darba veids | E18: 384 | F18: Vidēja | G18: Darba veids nav skaidrs | H18: Ronalds Gatavotājs TW Pumpists | J18: Dārzciema iela 384 m2 71 līme 10.02.26 | K18: Pārskatīt
A19: WR-2026-0059 | B19: 46063 | C19: Dārzciema iela 86 | D19: Estrich | E19: 172 | F19: Vidēja | G19: Iespējams dublikāts avota ziņai Nr. 346 | H19: Dāvis Estrich Limeni Jaunā Brigāde | I19: 00000347-PHOTO-2026-02-10-20-09-40.jpg | J19: Dārzciema iela 86 172m2 estrich 40maisi cements 10.02.26 <attached: 00000347-PHOTO-2026-02-10-20-09-40.jpg> | K19: Pārskatīt
A20: WR-2026-0060 | B20: 46063 | C20: Pasta iela 63 Jelgava | D20: Jānosaka darba veids | E20: 175 | F20: Vidēja | G20: Darba veids nav skaidrs | H20: Granulas 8eur/gab. | J20: Pasta iela 63 Jelgava 175m2 Līme 135 10.02.26 | K20: Pārskatīt
A21: WR-2026-0062 | B21: 46064 | C21: Dārzciema iela | D21: Jānosaka darba veids | E21: 345 | F21: Vidēja | G21: Darba veids nav skaidrs | H21: Ronalds Gatavotājs TW Pumpists | J21: Dārzciema iela 345 m2 61 līmē 11.02.26 | K21: Pārskatīt
A22: WR-2026-0064 | B22: 46064 | C22: Dārzciema iela 86 | D22: Estrich | E22: 232 | F22: Vidēja | G22: Iespējams dublikāts avota ziņai Nr. 350 | H22: Dāvis Estrich Limeni Jaunā Brigāde | I22: 00000351-PHOTO-2026-02-11-18-42-06.jpg | J22: Dārzciema iela 86 232m2 estrich 55maisi cements 11.02.26 <attached: 00000351-PHOTO-2026-02-11-18-42-06.jpg> | K22: Pārskatīt
A23: WR-2026-0066 | B23: 46065 | C23: Barona iela 119 | D23: Thermowhite | E23: 215 | F23: Vidēja | G23: Multivide piesaistīta pēc laika tuvuma | H23: Ronalds Gatavotājs TW Pumpists | I23: 00000363-PHOTO-2026-02-12-18-51-45.jpg | J23: Barona iela 215 m2 60 līmes 2 stāvs 12.02.26 | K23: Pārskatīt
A24: WR-2026-0068 | B24: 46065 | C24: Dārzciema iela 86 | D24: Estrich | E24: 135 | F24: Vidēja | G24: Iespējams dublikāts avota ziņai Nr. 365 | H24: Dāvis Estrich Limeni Jaunā Brigāde | I24: 00000366-PHOTO-2026-02-12-19-32-08.jpg | J24: Dārzciema iela 86 135m2 estrich 40maisi cements 2.stāvs <attached: 00000366-PHOTO-2026-02-12-19-32-08.jpg> | K24: Pārskatīt
A25: WR-2026-0069 | B25: 46065 | C25: Expon | D25: Jānosaka darba veids | E25: 427 | F25: Vidēja | G25: Darba veids nav skaidrs | H25: Kristers Cebulis | I25: 00000359-PHOTO-2026-02-12-18-35-59.jpg | J25: Expon 4 stāvs Dārzciema iela 86 (11.02.26 2 brigādes) (12.02.26 1 brigāde ) 427m2 <attached: 00000359-PHOTO-2026-02-12-18-35-59.jpg> | K25: Pārskatīt
A26: WR-2026-0070 | B26: 46065 | C26: Jānosaka projekts | D26: Jānosaka darba veids | E26: 427 | F26: Zema | G26: Projektu nevar droši noteikt; Darba veids nav skaidrs | H26: Kristers Cebulis | J26: 427m2 | K26: Pārskatīt
A27: WR-2026-0071 | B27: 46066 | C27: Barona iela 119 | D27: Jānosaka darba veids | E27: 264 | F27: Vidēja | G27: Darba veids nav skaidrs; Multivide piesaistīta pēc laika tuvuma | H27: Ronalds Gatavotājs TW Pumpists | I27: 00000372-PHOTO-2026-02-13-21-26-18.jpg | J27: Barona iela 264 m2 61 līme 13.02.26 | K27: Pārskatīt
A28: WR-2026-0074 | B28: 46066 | C28: Krustabaznīcas iela | D28: Jānosaka darba veids | E28: 78 | F28: Vidēja | G28: Darba veids nav skaidrs | H28: Artis Expon Briško | I28: 00000367-PHOTO-2026-02-13-07-16-32.jpg | J28: 12.02 Krustabaznīcas 11 78m² 10cm slānis <attached: 00000367-PHOTO-2026-02-13-07-16-32.jpg> | K28: Pārskatīt
A29: WR-2026-0077 | B29: 46067 | C29: Lietuva | D29: Thermowhite | F29: Vidēja | G29: Nav norādīts m² apjoms | H29: Ronalds Gatavotājs TW Pumpists | J29: 14.02.26 Lietuva 49 līmes | K29: Pārskatīt
A30: WR-2026-0082 | B30: 46069 | C30: Dārzciema iela 86 | D30: Estrich | E30: 207 | F30: Vidēja | G30: Iespējams dublikāts avota ziņai Nr. 376 | H30: Dāvis Estrich Limeni Jaunā Brigāde | I30: 00000377-PHOTO-2026-02-16-19-24-51.jpg | J30: Dārzciema iela 86 207m2 estrich 65maisi cements 2.stāvs 16.02.26 <attached: 00000377-PHOTO-2026-02-16-19-24-51.jpg> | K30: Pārskatīt
A31: WR-2026-0087 | B31: 46071 | C31: Dārzciema iela 86 | D31: Estrich | E31: 89 | F31: Vidēja | G31: Iespējams dublikāts avota ziņai Nr. 383 | H31: Dāvis Estrich Limeni Jaunā Brigāde | I31: 00000384-PHOTO-2026-02-18-21-16-06.jpg | J31: Dārzciema iela 86 89m2 estrich 2.stāvs 155m2 estrich 3.stāvs 60maisi cements 18.02.26 <attached: 00000384-PHOTO-2026-02-18-21-16-06.jpg> | K31: Pārskatīt
A32: WR-2026-0088 | B32: 46071 | C32: Dārzciema iela 86 | D32: Estrich | E32: 155 | F32: Vidēja | G32: Iespējams dublikāts avota ziņai Nr. 383 | H32: Dāvis Estrich Limeni Jaunā Brigāde | I32: 00000384-PHOTO-2026-02-18-21-16-06.jpg | J32: Dārzciema iela 86 89m2 estrich 2.stāvs 155m2 estrich 3.stāvs 60maisi cements 18.02.26 <attached: 00000384-PHOTO-2026-02-18-21-16-06.jpg> | K32: Pārskatīt
A33: WR-2026-0089 | B33: 46071 | C33: Jānosaka projekts | D33: Thermowhite | E33: 330 | F33: Zema | G33: Projektu nevar droši noteikt | H33: Ronalds Gatavotājs TW Pumpists | J33: 16.02 83 līmes 330m2 17.02 179 līmes 200 m2 18.02. 50 līmes 200 m2 | K33: Pārskatīt
A34: WR-2026-0090 | B34: 46071 | C34: Jānosaka projekts | D34: Thermowhite | E34: 200 | F34: Zema | G34: Projektu nevar droši noteikt | H34: Ronalds Gatavotājs TW Pumpists | J34: 16.02 83 līmes 330m2 17.02 179 līmes 200 m2 18.02. 50 līmes 200 m2 | K34: Pārskatīt
A35: WR-2026-0091 | B35: 46071 | C35: Jānosaka projekts | D35: Thermowhite | E35: 200 | F35: Zema | G35: Projektu nevar droši noteikt | H35: Ronalds Gatavotājs TW Pumpists | J35: 16.02 83 līmes 330m2 17.02 179 līmes 200 m2 18.02. 50 līmes 200 m2 | K35: Pārskatīt
A36: WR-2026-0095 | B36: 46072 | C36: Dārzciema iela 86 | D36: Estrich | E36: 150 | F36: Vidēja | G36: Iespējams dublikāts avota ziņai Nr. 389 | H36: Dāvis Estrich Limeni Jaunā Brigāde | I36: 00000390-PHOTO-2026-02-20-08-11-48.jpg | J36: Dārzciema iela 86 150m2 estrich 45maisi cements 3.stāvs 19.02.26 <attached: 00000390-PHOTO-2026-02-20-08-11-48.jpg> | K36: Pārskatīt
A37: WR-2026-0096 | B37: 46072 | C37: Jānosaka projekts | D37: Estrich | E37: 45 | F37: Zema | G37: Projektu nevar droši noteikt | H37: Artis Expon Briško | I37: 00000391-PHOTO-2026-02-20-14-15-18.jpg | J37: 19.02. Estrich 1. stāvs 45m² TW 2. stāvs 60m² <attached: 00000391-PHOTO-2026-02-20-14-15-18.jpg> | K37: Pārskatīt
A38: WR-2026-0097 | B38: 46072 | C38: Jānosaka projekts | D38: Estrich + Thermowhite | E38: 60 | F38: Zema | G38: Projektu nevar droši noteikt | H38: Artis Expon Briško | I38: 00000391-PHOTO-2026-02-20-14-15-18.jpg | J38: 19.02. Estrich 1. stāvs 45m² TW 2. stāvs 60m² <attached: 00000391-PHOTO-2026-02-20-14-15-18.jpg> | K38: Pārskatīt
A39: WR-2026-0100 | B39: 46073 | C39: Dārzciema iela 86 | D39: Estrich | E39: 190 | F39: Vidēja | G39: Iespējams dublikāts avota ziņai Nr. 393 | H39: Dāvis Estrich Limeni Jaunā Brigāde | I39: 00000394-PHOTO-2026-02-20-17-19-15.jpg | J39: Dārzciema iela 86 190m2 estrich 2.stāvs 60maisi cements 20.02.26 <attached: 00000394-PHOTO-2026-02-20-17-19-15.jpg> | K39: Pārskatīt
A40: WR-2026-0101 | B40: 46073 | C40: Jānosaka projekts | D40: Estrich | E40: 60 | F40: Zema | G40: Projektu nevar droši noteikt | H40: Artis Expon Briško | I40: 00000392-PHOTO-2026-02-20-14-16-22.jpg | J40: 20.02. Estrich 2. stāvs 60m² Estrich pagrabs 15m² TW 2. stāvs 38m² <attached: 00000392-PHOTO-2026-02-20-14-16-22.jpg> | K40: Pārskatīt
A41: WR-2026-0102 | B41: 46073 | C41: Jānosaka projekts | D41: Estrich | E41: 15 | F41: Zema | G41: Projektu nevar droši noteikt | H41: Artis Expon Briško | I41: 00000392-PHOTO-2026-02-20-14-16-22.jpg | J41: 20.02. Estrich 2. stāvs 60m² Estrich pagrabs 15m² TW 2. stāvs 38m² <attached: 00000392-PHOTO-2026-02-20-14-16-22.jpg> | K41: Pārskatīt
...

Sheet Avota ziņas
A1: Visas 2026. gada WhatsApp ziņas
A2: Saglabātas 659 ziņas auditam. Klasifikācija ir automātiska un rediģējama.
A4: Ziņas Nr. | B4: Ziņas datums | C4: Laiks | D4: Autors | E4: Klasifikācija | F4: Iespējamais projekts | G4: Multivides faili | H4: Rediģēta | I4: Pilns avota teksts
A5: 273 | B5: 46023 | C5: 20:08:08 | D5: Gundars TW Staravoitovs | E5: Instrukcija / administrācija | F5: Jānosaka projekts | H5: Nē | I5: Sveiciens visiem jaunajā gadā! Rītdienas darba dienu pārceļam uz 10.01 vai 17.01, lai visiem ražīgs jaunais gads! 🥳
A6: 274 | B6: 46027 | C6: 17:13:45 | D6: Dāvis Estrich Limeni Jaunā Brigāde | E6: Iespējams dienas ieraksts | F6: Dzirciema iela 16 | H6: Nē | I6: Dzirciema iela 16, Rīga 300m2 Thermo 69maisi līme 05.01.2026
A7: 275 | B7: 46027 | C7: 18:08:59 | D7: Ronalds Gatavotājs TW Pumpists | E7: Iespējams dienas ieraksts | F7: Barona iela 119 | H7: Nē | I7: Barona iela 119 235 m2 49 līmes 05.01.26.
A8: 276 | B8: 46028 | C8: 15:48:27 | D8: Edijs Vinvalks | E8: Iespējams dienas ieraksts | F8: Kadaga DEPO | H8: Nē | I8: Kadaga DEPO - Visa platība aizpildītas šuves starp pamatni un sienām + kāpnes PENOSIL 8GB + SILKA 4GB 06.01.2026
A9: 277 | B9: 46028 | C9: 16:53:44 | D9: Artis Expon Briško | E9: Iespējams dienas ieraksts | F9: Vēžu iela 4, Roja | H9: Nē | I9: Roja Vēžu iela 4 TW 113m² 34 līmes un granulas
A10: 278 | B10: 46028 | C10: 18:20:05 | D10: Ronalds Gatavotājs TW Pumpists | E10: Iespējams dienas ieraksts | F10: Barona iela 119 | H10: Nē | I10: Barona iela 119 293 m2 69 līmes 06.01.26
A11: 279 | B11: 46029 | C11: 16:02:12 | D11: Dāvis Estrich Limeni Jaunā Brigāde | E11: Iespējams dienas ieraksts | F11: Dzirciema iela 16 | H11: Jā | I11: Dzirciema iela 16, Rīga 240m2 estrich + plēve 60 maisi cements 7.1.26 <This message was edited>
A12: 280 | B12: 46030 | C12: 11:43:13 | D12: Ronalds Gatavotājs TW Pumpists | E12: Iespējams dienas ieraksts | F12: Barona iela 119 | H12: Nē | I12: Barona 224m2 69 līmes 07.01.26
A13: 281 | B13: 46030 | C13: 20:56:41 | D13: Ronalds Gatavotājs TW Pumpists | E13: Iespējams dienas ieraksts | F13: Kadaga | H13: Nē | I13: Kadaga 360 m2 73 līmes 08.01.26
A14: 282 | B14: 46031 | C14: 20:04:00 | D14: Ronalds Gatavotājs TW Pumpists | E14: Iespējams dienas ieraksts | F14: Raiņa iela 2A, Iecava | H14: Nē | I14: Iecava Raiņa iela 400m2 134 līmēs 09.01.26.
A15: 283 | B15: 46034 | C15: 19:03:45 | D15: Ronalds Gatavotājs TW Pumpists | E15: Iespējams dienas ieraksts | F15: Barona iela 119 | H15: Nē | I15: Barona iela 212 m2 70 līmes 12.01.26
A16: 284 | B16: 46034 | C16: 19:04:15 | D16: Ronalds Gatavotājs TW Pumpists | E16: Datuma turpinājums | F16: Jānosaka projekts | H16: Nē | I16: 12.01.26
... A28: 296 | B28: 46042 | C28: 07:21:25 | D28: Ronalds Gatavotājs TW Pumpists | E28: Iespējams dienas ieraksts | F28: Kadaga | H28: Nē | I28: Kadaga 347 m2 87 līmes 19.01.26
A29: 297 | B29: 46042 | C29: 08:05:49 | D29: Limeni! | E29: Multivide jāpārskata | F29: Jānosaka projekts | G29: 00000297-PHOTO-2026-01-20-08-05-49.jpg | H29: Nē | I29: Labrīt. <attached: 00000297-PHOTO-2026-01-20-08-05-49.jpg>
A30: 298 | B30: 46043 | C30: 08:02:45 | D30: Ronalds Gatavotājs TW Pumpists | E30: Iespējams dienas ieraksts | F30: Kadaga | H30: Nē | I30: Kadaga 274 m2 66 līmes 20.01.26.
A31: 299 | B31: 46043 | C31: 09:40:58 | D31: Gundars TW Staravoitovs | E31: Multivide jāpārskata | F31: Jānosaka projekts | G31: 00000299-PHOTO-2026-01-21-09-40-58.jpg | H31: Nē | I31: Paldies par lieliski sniegto informāciju. Šādi ieraksti ir ļoti labi. 💪 bet tagad iesim vienu solīti uz priekšu. Lielajos projektos nepieciešams OBLIGĀTI klāt plānu ar apvilktu zonu kurā veikti darbi. tas nepieciešams jo mums katru dienu jāraksta BIS (būvdarbu žurnāls) un no šīm izpildshēmām arī rēķinās jŪsu atalgojumu. (m2 tā pat mēram, tikai lai salīdzinātu vai plāni atbilst dabā izdarītajam) <attached: 00000299-PHOTO-2026-01-21-09-40-58.jpg>
A32: 300 | B32: 46043 | C32: 09:41:17 | D32: Gundars TW Staravoitovs | E32: Multivide jāpārskata | F32: Barona iela 119 | G32: 00000300-PHOTO-2026-01-21-09-41-17.jpg | H32: Nē | I32: uz bildes var nerakstīt datumu, un m2, galvenais apvilkt zonu kas izdarīta un tektā tad raksta: 16.01.2026 Barona iela 67m2 20 līmes <attached: 00000300-PHOTO-2026-01-21-09-41-17.jpg>
A33: 301 | B33: 46043 | C33: 09:41:53 | D33: Gundars TW Staravoitovs | E33: Instrukcija / administrācija | F33: Konkurenti jau tā dara, tā kā tas nav tikai mūsu izdomājums | H33: Nē | I33: Konkurenti jau tā dara, tā kā tas nav tikai mūsu izdomājums
A34: 302 | B34: 46043 | C34: 09:55:29 | D34: Gundars TW Staravoitovs | E34: Multivide jāpārskata | F34: Jānosaka projekts | G34: 00000302-PHOTO-2026-01-21-09-55-29.jpg | H34: Nē | I34: te kā lielajos objektos mums līgumā rakstīts, Mēs tikai tāpēc to prasam. Tikai kopīgi varam to izpildīt un saņemt naudu par paveikto. <attached: 00000302-PHOTO-2026-01-21-09-55-29.jpg>
A35: 303 | B35: 46043 | C35: 10:20:34 | D35: Gundars TW Staravoitovs | E35: Instrukcija / administrācija | F35: Jānosaka projekts | H35: Nē | I35: Plānus nosūtīs Kristers pirms darbu uzsākšanas, norā'dis arī plānoto dienas apjomu kas jāsasniedz
A36: 304 | B36: 46044 | C36: 09:34:18 | D36: Raivis /TW Vilcejs | E36: Cita sarakste | F36: Jānosaka projekts | H36: Nē | I36: Gundars TW Staravoitovs added Raivis /TW Vilcejs
A37: 305 | B37: 46044 | C37: 09:20:51 | D37: Ronalds Gatavotājs TW Pumpists | E37: Iespējams dienas ieraksts | F37: Kadaga | H37: Nē | I37: Kadaga 360 m2 76 līmes 21.02.26.
A38: 306 | B38: 46044 | C38: 15:46:46 | D38: Artis Expon Briško | E38: Iespējams dienas ieraksts | F38: Bērzaunes iela 15 | H38: Nē | I38: Bērzaunes 15 Estrich 90m²
A39: 307 | B39: 46044 | C39: 18:26:30 | D39: Dāvis Estrich Limeni Jaunā Brigāde | E39: Iespējams dienas ieraksts | F39: Barona iela 119 | G39: 00000307-PHOTO-2026-01-22-18-26-30.jpg | H39: Nē | I39: Barona iela 119 6.st. 155m2 estrich 65maisi cements 22.01.26 <attached: 00000307-PHOTO-2026-01-22-18-26-30.jpg>
A40: 308 | B40: 46045 | C40: 16:04:47 | D40: Artis Expon Briško | E40: Iespējams dienas ieraksts | F40: Bērzaunes iela 15 | H40: Nē | I40: Bērzaunes 15 Estrich 102m²
A41: 309 | B41: 46045 | C41: 18:37:23 | D41: Ronalds Gatavotājs TW Pumpists | E41: Iespējams dienas ieraksts | F41: Raiņa iela 2A, Iecava | H41: Nē | I41: Iecava Raiņa iela 400 170 līmes 23.01.26
A42: 310 | B42: 46045 | C42: 20:44:14 | D42: Dāvis Estrich Limeni Jaunā Brigāde | E42: Iespējams dienas ieraksts | F42: Barona iela 119 | G42: 00000310-PHOTO-2026-01-23-20-44-14.jpg | H42: Nē | I42: Barona iela 119 6.st. 160m2 estrich 70 maisi cements 23.01.26 <attached: 00000310-PHOTO-2026-01-23-20-44-14.jpg>
A43: 311 | B43: 46045 | C43: 20:44:15 | D43: Dāvis Estrich Limeni Jaunā Brigāde | E43: Iespējams dienas ieraksts | F43: Barona iela 119 | G43: 00000311-PHOTO-2026-01-23-20-44-15.jpg | H43: Nē | I43: Barona iela 119 6.st. 160m2 estrich 70 maisi cements 23.01.26 <attached: 00000311-PHOTO-2026-01-23-20-44-15.jpg>
A44: 312 | B44: 46046 | C44: 21:25:36 | D44: Granulas 8eur/gab. | E44: Iespējams dienas ieraksts | F44: Barona iela 119 | G44: 00000312-PHOTO-2026-01-24-21-25-36.jpg | H44: Nē | I44: Barona iela 119 5.st 107m2 Estrich 51maisi cements 24.01.2026 <attached: 00000312-PHOTO-2026-01-24-21-25-36.jpg>
A45: 313 | B45: 46048 | C45: 15:07:26 | D45: Artis Expon Briško | E45: Iespējams dienas ieraksts | F45: Bērzaunes iela 15 | H45: Nē | I45: Bērzaunes 15 Estrich 113m²
A46: 314 | B46: 46048 | C46: 21:09:34 | D46: Ronalds Gatavotājs TW Pumpists | E46: Iespējams dienas ieraksts | F46: Kadaga | H46: Nē | I46: Kadaga 279 m2 49 līmes 26.01.26
A47: 315 | B47: 46050 | C47: 14:53:13 | D47: Dāvis Estrich Limeni Jaunā Brigāde | E47: Iespējams dienas ieraksts | F47: Raiņa iela 2A, Iecava | H47: Nē | I47: Iecava, Raiņa iela 2A 290m2 estrich + plēve 85maisi cements 27.01. - 28.01.
A48: 316 | B48: 46050 | C48: 19:46:31 | D48: Ronalds Gatavotājs TW Pumpists | E48: Iespējams dienas ieraksts | F48: Jūrmalas gatve 51 | H48: Nē | I48: Jūrmalas gatve 51 28 līmes 28.01.26
